Workbook

Sheet Z0000002-508684 BOM triển k hai
A1: CONVEYOR_Z0000002-508684_ Code_Conveyor_Shutter 2 | H1: SL | I1: 2 | J1: ='[1]ducpt trien khai'!$I$27 -> 12
A2: Image | B2: ID Number | C2: Quantity | D2: BOM gốc | E2: Ghi chú | F2: Category | G2: Visible Part Size | H2: NCC/vật tư | I2: SL | K2: =I44 -> triển khai lần 1, sl 2 | L2: Triển khai lần 2 | R2: giống cột E
B3: AB01 | C3: 1 | D3: TTBU250T5-100_info-1-18-18_1 | E3: TTBU250T5-100 --> đổi sang C-TTBN250T5-150 | G3: 110.0 X 30.0 X 10.0 | H3: MI | I3: =C3*$I$1 -> 2 | J3: =$J$1*C3 -> 12 | K3: đã chốt đặt, dự kiến về trước 10/4 | L3: đã nhận đủ 13/4, | R3: =E3 -> TTBU250T5-100 --> đổi sang C-TTBN250T5-150
B4: AB02 | C4: 1 | D4: MF_SUS304_1244 | E4: SUS304, điện hóa | G4: 25.0 X 53.0 X 51.0 | H4: CG | I4: =C4*$I$1 -> 2 | J4: =$J$1*C4 -> 12 | K4: đã chốt HH | R4: =E4 -> SUS304, điện hóa
B5: AB03 | C5: 2 | D5: MF_SUS304_0210_1432 | E5: =E4 -> SUS304, điện hóa | G5: 20.0 X 50.0 X 25.0 | H5: =H4 -> CG | I5: =C5*$I$1 -> 4 | J5: =$J$1*C5 -> 24 | K5: =K4 -> đã chốt HH | R5: =E5 -> SUS304, điện hóa
B6: AB04 | C6: 1 | D6: MF_SUS204_1143 | E6: =E5 -> SUS304, điện hóa | G6: 25.0 X 63.0 X 56.0 | H6: =H5 -> CG | I6: =C6*$I$1 -> 2 | J6: =$J$1*C6 -> 12 | K6: =K5 -> đã chốt HH | R6: =E6 -> SUS304, điện hóa
B7: AB05 | C7: 1 | D7: MF_Aluminum 6061_0202_176 | E7: AL6061 anode đen | G7: 260.0 X 150.0 X 8.0 | H7: GTAM | I7: =C7*$I$1 -> 2 | J7: =$J$1*C7 -> 12 | K7: đã xong 9/4 | R7: =E7 -> AL6061 anode đen
B8: AB06 | C8: 1 | D8: HTPA18S5M100-A-N8-FC30.0 | E8: HTPA18S5M100-A-N8-FC30.0 đổi sang HTPA18S5M150-A-N8-FC30.0 | G8: 31.0 X 16.0 X 31.0 | H8: UP | I8: =C8*$I$1 -> 2 | J8: =$J$1*C8 -> 12 | K8: =K3 -> đã chốt đặt, dự kiến về trước 10/4 | R8: =E8 -> HTPA18S5M100-A-N8-FC30.0 đổi sang HTPA18S5M150-A-N8-FC30.0
B9: AB07 | C9: 1 | D9: CV3_Pb108_Shutter 2_MIR | E9: PB108 | G9: 395.0 X 19.0 X 10.0 | H9: GTAM | I9: =C9*$I$1 -> 2 | J9: =$J$1*C9 -> 12 | K9: 9/4 đã xong | R9: =E9 -> PB108
B10: AB08 | C10: 1 | D10: CV3_Pb108_Shutter 2 | E10: =E9 -> PB108 | G10: 395.0 X 19.0 X 10.0 | H10: =H9 -> GTAM | I10: =C10*$I$1 -> 2 | J10: =$J$1*C10 -> 12 | K10: =K9 -> 9/4 đã xong | R10: =E10 -> PB108
B11: AB09 | C11: 2 | D11: CV3_Pb108-1_UV | E11: =E10 -> PB108 | G11: 344.0 X 26.0 X 16.0 | H11: =H10 -> GTAM | I11: =C11*$I$1 -> 4 | J11: =$J$1*C11 -> 24 | K11: =K10 -> 9/4 đã xong | R11: =E11 -> PB108
B12: AB10 | C12: 2 | D12: CV3_Belt 1_Shutter 2 | E12: belt PU đen, chống tĩnh điện, ép viền chống xước, dày 1.5mm, bản rộng 20mm, chu vi 890mm( đo mép trong 895mm, chốt cân chỉnh đang ở giữa ) | G12: 394.0 X 20.0 X 80.0 | H12: Belt | I12: =C12*$I$1 -> 4 | J12: =$J$1*C12 -> 24 | K12: đã nhận đủ hàng 9/4 | L12: đã đặt hàng 10/4, hẹn 25/4 giao 50%, 5/5 giao nốt | R12: =E12 -> belt PU đen, chống tĩnh điện, ép viền chống xước, dày 1.5mm, bản rộng 20mm, chu vi 890mm( đo mép trong 895mm, chốt cân chỉnh đang ở giữa )
B13: AB11 | C13: 1 | D13: CV3_AL_Shutter 2 | E13: =E7 -> AL6061 anode đen | G13: 395.0 X 12.0 X 89.0 | H13: =H11 -> GTAM | I13: =C13*$I$1 -> 2 | J13: =$J$1*C13 -> 12 | K13: =K11 -> 9/4 đã xong | R13: =E13 -> AL6061 anode đen
B14: AB12 | C14: 1 | D14: CV3_AL_Shutter 2 MIR | E14: =E13 -> AL6061 anode đen | G14: 395.0 X 12.0 X 89.0 | H14: =H13 -> GTAM | I14: =C14*$I$1 -> 2 | J14: =$J$1*C14 -> 12 | K14: =K13 -> 9/4 đã xong | R14: =E14 -> AL6061 anode đen
B15: AB13 | C15: 1 | D15: CV3_AL 9 Shutter 2 | E15: =E14 -> AL6061 anode đen | G15: 60.0 X 20.0 X 63.0 | H15: =H14 -> GTAM | I15: =C15*$I$1 -> 2 | J15: =$J$1*C15 -> 12 | K15: =K14 -> 9/4 đã xong | R15: =E15 -> AL6061 anode đen
B16: AB14 | C16: 1 | D16: CV3_AL 32_Shutter 2 | E16: =E15 -> AL6061 anode đen | G16: 245.0 X 200.0 X 12.0 | H16: =H15 -> GTAM | I16: =C16*$I$1 -> 2 | J16: =$J$1*C16 -> 12 | K16: =K15 -> 9/4 đã xong | R16: =E16 -> AL6061 anode đen
B17: AB15 | C17: 1 | D17: CV3_AL 10. | E17: =E16 -> AL6061 anode đen | G17: 15.0 X 8.0 X 35.0 | H17: =H16 -> GTAM | I17: =C17*$I$1 -> 2 | J17: =$J$1*C17 -> 12 | K17: =K16 -> 9/4 đã xong | R17: =E17 -> AL6061 anode đen
B18: AB16 | C18: 1 | D18: S6I06G-GX | E18: S6I06GX-12CE và bộ đk tốc độ SUA06IX-V12 | G18: 100.0 X 60.0 X 62.0 | H18: SPG | I18: =C18*$I$1 -> 2 | J18: =$J$1*C18 -> 12 | K18: NG báo đã nhận 27 set, đủ lô 7CV | R18: =E18 -> S6I06GX-12CE và bộ đk tốc độ SUA06IX-V12
B19: AB17 | C19: 1 | D19: S6KA3-15 | E19: hộp số S6KA15B | G19: 60.0 X 60.0 X 63.0 | H19: =H18 -> SPG | I19: =C19*$I$1 -> 2 | J19: =$J$1*C19 -> 12 | K19: =K18 -> NG báo đã nhận 27 set, đủ lô 7CV | R19: =E19 -> hộp số S6KA15B
B20: AB18 | C20: 1 | D20: KES3-12 | E20: Chốt cài KES-12 | G20: 12.0 X 3.0 X 3.0 | H20: Chốt cài | I20: =C20*$I$1 -> 2 | J20: =$J$1*C20 -> 12 | K20: đã tồn kho | R20: =E20 -> Chốt cài KES-12
B21: AB19 | C21: 1 | D21: MF_Al6061_841 | E21: =E17 -> AL6061 anode đen | G21: 10.0 X 70.0 X 70.0 | H21: =H17 -> GTAM | I21: =C21*$I$1 -> 2 | J21: =$J$1*C21 -> 12 | K21: =K17 -> 9/4 đã xong | R21: =E21 -> AL6061 anode đen
B22: AB20 | C22: 1 | D22: MF_Al6061_845 | E22: =E21 -> AL6061 anode đen | G22: 16.0 X 25.0 X 62.0 | H22: =H21 -> GTAM | I22: =C22*$I$1 -> 2 | J22: =$J$1*C22 -> 12 | K22: =K21 -> 9/4 đã xong | R22: =E22 -> AL6061 anode đen
B23: AB21 | C23: 1 | D23: MF_Urethan 90_1119 | E23: Urethan | G23: 15.0 X 8.0 X 35.0 | H23: =H22 -> GTAM | I23: =C23*$I$1 -> 2 | J23: =$J$1*C23 -> 12 | K23: =K22 -> 9/4 đã xong | R23: =E23 -> Urethan
B24: AB22 | C24: 4 | D24: CV3_Pulley 1 | E24: Rulo | G24: 24.0 X 23.0 X 24.0 | H24: TT | I24: =C24*$I$1 -> 8 | J24: =$J$1*C24 -> 48 | K24: đã giao lô đầu 30 set | L24: 9/4 nhận 159 bộ, thiếu rulo chủ động giao sau | R24: =E24 -> Rulo
B25: AB23 | C25: 16 | D25: SB688ZZ | E25: Vòng bi SB688ZZ --> đổi sang C-SE688ZZ | G25: 16.0 X 5.0 X 16.0 | H25: VB C-SE688ZZ | I25: =C25*$I$1 -> 32 | J25: =$J$1*C25 -> 192 | K25: đặt tổng 432, đã về hàng 9/4 | L25: Tổng lô đặt HC 2280, 14/4 về trc 630 | R25: =E25 -> Vòng bi SB688ZZ --> đổi sang C-SE688ZZ
B26: AB24 | C26: 2 | D26: CV3_Shaft 5 | E26: SUS304, điện hóa | G26: 12.0 X 30.0 X 12.0 | H26: =H24 -> TT | I26: =C26*$I$1 -> 4 | J26: =$J$1*C26 -> 24 | K26: =K24 -> đã giao lô đầu 30 set | L26: =L24 -> 9/4 nhận 159 bộ, thiếu rulo chủ động giao sau | R26: =E26 -> SUS304, điện hóa
B27: AB25 | C27: 8 | D27: STWN8_Misumi | E27: Phanh trục STWN8 | G27: 1.0 X 10.0 X 13.0 | H27: Phanh trục | I27: =C27*$I$1 -> 16 | J27: =$J$1*C27 -> 96 | K27: đã tồn kho sẵn | R27: =E27 -> Phanh trục STWN8
B28: AB26 | C28: 4 | D28: CV3_Pulley | E28: Rulo | G28: 21.0 X 20.0 X 21.0 | H28: =H24 -> TT | I28: =C28*$I$1 -> 8 | J28: =$J$1*C28 -> 48 | K28: =K24 -> đã giao lô đầu 30 set | L28: =L26 -> 9/4 nhận 159 bộ, thiếu rulo chủ động giao sau | R28: =E28 -> Rulo
B29: AB27 | C29: 4 | D29: CV3_Shaft 1 | E29: =E26 -> SUS304, điện hóa | G29: 12.0 X 29.0 X 12.0 | H29: =H26 -> TT | I29: =C29*$I$1 -> 8 | J29: =$J$1*C29 -> 48 | K29: =K28 -> đã giao lô đầu 30 set | L29: =L28 -> 9/4 nhận 159 bộ, thiếu rulo chủ động giao sau | R29: =E29 -> SUS304, điện hóa
B30: AB28 | C30: 1 | D30: CV3_Shaft 4 | E30: Trục | G30: 11.0 X 10.0 X 205.0 | H30: =H28 -> TT | I30: =C30*$I$1 -> 2 | J30: =$J$1*C30 -> 12 | K30: =K28 -> đã giao lô đầu 30 set | L30: =L29 -> 9/4 nhận 159 bộ, thiếu rulo chủ động giao sau | R30: =E30 -> Trục
B31: AB29 | C31: 2 | D31: CV3_Pulley 2 | E31: Rulo | G31: 34.0 X 31.0 X 34.0 | H31: =H30 -> TT | I31: =C31*$I$1 -> 4 | J31: =$J$1*C31 -> 24 | K31: =K30 -> đã giao lô đầu 30 set | L31: =L30 -> 9/4 nhận 159 bộ, thiếu rulo chủ động giao sau | R31: =E31 -> Rulo
B32: AB30 | C32: 2 | D32: SB6000ZZ | E32: Vòng bi SB6000ZZ --> đổi sang C-SE6000ZZ | G32: 26.0 X 8.0 X 26.0 | H32: VB C-SE6000ZZ | I32: =C32*$I$1 -> 4 | J32: =$J$1*C32 -> 24 | K32: đã nhận hàng 27/3 | L32: tổng lô 324, đã về đủ 13/4 | R32: =E32 -> Vòng bi SB6000ZZ --> đổi sang C-SE6000ZZ
B33: AB31 | C33: 2 | D33: STWN10 | E33: phanh trục STWN10 | G33: 1.0 X 15.0 X 13.0 | H33: =H27 -> Phanh trục | I33: =C33*$I$1 -> 4 | J33: =$J$1*C33 -> 24 | K33: =K27 -> đã tồn kho sẵn | R33: =E33 -> phanh trục STWN10
B34: AB32 | C34: 1 | D34: HTPA18S5M100-B-N10-FC30.0_Misumi | E34: HTPA18S5M100-B-N10-FC30.0 đổi sang HTPA18S5M150-B-N10-FC30.0 | G34: 28.0 X 30.0 X 30.0 | H34: UP | I34: =C34*$I$1 -> 2 | J34: =$J$1*C34 -> 12 | K34: =K8 -> đã chốt đặt, dự kiến về trước 10/4 | R34: =E34 -> HTPA18S5M100-B-N10-FC30.0 đổi sang HTPA18S5M150-B-N10-FC30.0
B35: AB33 | C35: 3 | D35: KES3-15 | E35: Chốt cài KES-15 | G35: 15.0 X 3.0 X 3.0 | H35: Chốt cài | I35: =C35*$I$1 -> 6 | J35: =$J$1*C35 -> 36 | K35: =K20 -> đã tồn kho | R35: =E35 -> Chốt cài KES-15
B36: AB34 | C36: 2 | D36: CV3_Shaft 3 | E36: SUS304, điện hóa | G36: 12.0 X 34.0 X 12.0 | H36: =H26 -> TT | I36: =C36*$I$1 -> 4 | J36: =$J$1*C36 -> 24 | K36: =K29 -> đã giao lô đầu 30 set | L36: =L31 -> 9/4 nhận 159 bộ, thiếu rulo chủ động giao sau | R36: =E36 -> SUS304, điện hóa
B37: AB35 | C37: 2 | D37: CV3_AL 7 | E37: =E22 -> AL6061 anode đen | G37: 15.0 X 8.0 X 35.0 | H37: =H23 -> GTAM | I37: =C37*$I$1 -> 4 | J37: =$J$1*C37 -> 24 | K37: =K23 -> 9/4 đã xong | R37: =E37 -> AL6061 anode đen
B38: AB36 | C38: 2 | D38: CV3_AL 8 | E38: =E37 -> AL6061 anode đen | G38: 22.0 X 8.0 X 35.0 | H38: =H37 -> GTAM | I38: =C38*$I$1 -> 4 | J38: =$J$1*C38 -> 24 | K38: =K37 -> 9/4 đã xong | R38: =E38 -> AL6061 anode đen
B39: AB37 | C39: 2 | D39: MF_Aluminum 6061_0202_1757 | E39: =E38 -> AL6061 anode đen | G39: 150.0 X 43.0 X 15.0 | H39: =H38 -> GTAM | I39: =C39*$I$1 -> 4 | J39: =$J$1*C39 -> 24 | K39: =K38 -> 9/4 đã xong | R39: =E39 -> AL6061 anode đen
B40: AB38 | C40: 2 | D40: MF_Aluminum 6061_0202_179 | E40: =E39 -> AL6061 anode đen | G40: 100.0 X 35.0 X 8.0 | H40: =H39 -> GTAM | I40: =C40*$I$1 -> 4 | J40: =$J$1*C40 -> 24 | K40: =K39 -> 9/4 đã xong | R40: =E40 -> AL6061 anode đen
...

Sheet Z0000002-508700 BOM triển k hai
A1: CONVEYOR_Z0000002-508700_ Code_Conveyor_UV - BOM | H1: SL | I1: 4 | J1: ='[1]ducpt trien khai'!$I$28 -> 24
A2: Image | B2: ID Number | C2: Quantity | D2: Standard Number | E2: Sub Category | F2: Category | G2: Visible Part Size | H2: NCC/vật tư | I2: Lần 1 | J2: lần 2
B3: AC01 | C3: 1 | D3: CV3_Pb108_UV | E3: PB108 | G3: 150.0 X 20.0 X 10.0 | H3: GTAM | I3: =C3*$I$1 -> 4 | J3: =$J$1*C3 -> 24 | K3: chưa gc
B4: AC02 | C4: 2 | D4: Auto CTQ Machine - Conveyor - P034 copy | E4: =VLOOKUP(G4,'Z0000002-508684 BOM triển k hai'!$G$3:$R$42,11,0) -> 0 | G4: 25.0 X 63.0 X 56.0 | H4: =VLOOKUP(G4,'Z0000002-508684 BOM triển k hai'!$G$3:$H$42,2,0) -> CG | I4: =C4*$I$1 -> 8 | J4: =$J$1*C4 -> 48
B5: AC03 | C5: 1 | D5: MF_PB108_1404 | E5: =E3 -> PB108 | G5: 83.0 X 11.0 X 20.0 | H5: =H3 -> GTAM | I5: =C5*$I$1 -> 4 | J5: =$J$1*C5 -> 24 | K5: chưa gc
B6: AC04 | C6: 1 | D6: CV3_Pb108_UV_MIR | E6: =E5 -> PB108 | G6: 396.0 X 20.0 X 22.0 | H6: =H5 -> GTAM | I6: =C6*$I$1 -> 4 | J6: =$J$1*C6 -> 24 | K6: chưa gc
B7: AC05 | C7: 1 | D7: CV3_AL 2 _UV_53 | E7: =VLOOKUP(G7,'Z0000002-508684 BOM triển k hai'!$G$3:$R$42,12,0) -> AL6061 anode đen | G7: 395.0 X 12.0 X 89.0 | H7: =VLOOKUP(G7,'Z0000002-508684 BOM triển k hai'!$G$3:$H$42,2,0) -> GTAM | I7: =C7*$I$1 -> 4 | J7: =$J$1*C7 -> 24 | K7: đã xong
B8: AC06 | C8: 1 | D8: CV3_AL 9 uv | E8: =VLOOKUP(G8,'Z0000002-508684 BOM triển k hai'!$G$3:$R$42,12,0) -> AL6061 anode đen | G8: 60.0 X 20.0 X 63.0 | H8: =VLOOKUP(G8,'Z0000002-508684 BOM triển k hai'!$G$3:$H$42,2,0) -> GTAM | I8: =C8*$I$1 -> 4 | J8: =$J$1*C8 -> 24 | K8: đã xong
B9: AC07 | C9: 1 | D9: HTPA18S5M100-A-N8-FC30.0 | E9: =VLOOKUP(G9,'Z0000002-508684 BOM triển k hai'!$G$3:$R$42,12,0) -> HTPA18S5M100-A-N8-FC30.0 đổi sang HTPA18S5M150-A-N8-FC30.0 | G9: 31.0 X 16.0 X 31.0 | H9: =VLOOKUP(G9,'Z0000002-508684 BOM triển k hai'!$G$3:$H$42,2,0) -> UP | I9: =C9*$I$1 -> 4 | J9: =$J$1*C9 -> 24
B10: AC08 | C10: 1 | D10: CV3_AL 10. | E10: =VLOOKUP(G10,'Z0000002-508684 BOM triển k hai'!$G$3:$R$42,12,0) -> AL6061 anode đen | G10: 15.0 X 8.0 X 35.0 | H10: =VLOOKUP(G10,'Z0000002-508684 BOM triển k hai'!$G$3:$H$42,2,0) -> GTAM | I10: =C10*$I$1 -> 4 | J10: =$J$1*C10 -> 24 | K10: đã xong
B11: AC09 | C11: 1 | D11: TTBU250T5-100_info-1-18-18_1 | E11: =VLOOKUP(G11,'Z0000002-508684 BOM triển k hai'!$G$3:$R$42,12,0) -> TTBU250T5-100 --> đổi sang C-TTBN250T5-150 | G11: 110.0 X 30.0 X 10.0 | H11: =VLOOKUP(G11,'Z0000002-508684 BOM triển k hai'!$G$3:$H$42,2,0) -> MI | I11: =C11*$I$1 -> 4 | J11: =$J$1*C11 -> 24
B12: AC10 | C12: 2 | D12: CV3_Belt 1_UV | E12: =VLOOKUP(G12,'Z0000002-508684 BOM triển k hai'!$G$3:$R$42,12,0) -> belt PU đen, chống tĩnh điện, ép viền chống xước, dày 1.5mm, bản rộng 20mm, chu vi 890mm( đo mép trong 895mm, chốt cân chỉnh đang ở giữa ) | G12: 394.0 X 20.0 X 80.0 | H12: =VLOOKUP(G12,'Z0000002-508684 BOM triển k hai'!$G$3:$H$42,2,0) -> Belt | I12: =C12*$I$1 -> 8 | J12: =$J$1*C12 -> 48
B13: AC11 | C13: 2 | D13: CV3_Pb108-1_UV | E13: =VLOOKUP(G13,'Z0000002-508684 BOM triển k hai'!$G$3:$R$42,12,0) -> PB108 | G13: 344.0 X 26.0 X 16.0 | H13: =VLOOKUP(G13,'Z0000002-508684 BOM triển k hai'!$G$3:$H$42,2,0) -> GTAM | I13: =C13*$I$1 -> 8 | J13: =$J$1*C13 -> 48 | K13: chưa gc
B14: AC12 | C14: 1 | D14: CV3_AL 2 _UV_3 | E14: =VLOOKUP(G14,'Z0000002-508684 BOM triển k hai'!$G$3:$R$42,12,0) -> AL6061 anode đen | G14: 395.0 X 12.0 X 89.0 | H14: =VLOOKUP(G14,'Z0000002-508684 BOM triển k hai'!$G$3:$H$42,2,0) -> GTAM | I14: =C14*$I$1 -> 4 | J14: =$J$1*C14 -> 24 | K14: đã xong
B15: AC13 | C15: 1 | D15: MF_SUS304_0210_1454_1 | E15: SUS304, điện hóa | G15: 10.0 X 40.0 X 29.0 | H15: CG | I15: =C15*$I$1 -> 4 | J15: =$J$1*C15 -> 24
B16: AC14 | C16: 1 | D16: MF_SUS304_0210_1454_MIR_1 | E16: =E15 -> SUS304, điện hóa | G16: 20.0 X 40.0 X 29.0 | H16: =H15 -> CG | I16: =C16*$I$1 -> 4 | J16: =$J$1*C16 -> 24
B17: AC15 | C17: 1 | D17: CV3_AL 3_UV | E17: =E14 -> AL6061 anode đen | G17: 395.0 X 200.0 X 12.0 | H17: =H14 -> GTAM | I17: =C17*$I$1 -> 4 | J17: =$J$1*C17 -> 24 | K17: đã xong
B18: AC16 | C18: 1 | D18: S6I06G-GX | E18: S6I06GX-12CE và bộ đk tốc độ SUD06IB-V12 | G18: 100.0 X 60.0 X 62.0 | H18: =VLOOKUP(G18,'Z0000002-508684 BOM triển k hai'!$G$3:$H$42,2,0) -> SPG | I18: =C18*$I$1 -> 4 | J18: =$J$1*C18 -> 24
B19: AC17 | C19: 1 | D19: S6KA3-15 | E19: =VLOOKUP(G19,'Z0000002-508684 BOM triển k hai'!$G$3:$R$42,12,0) -> hộp số S6KA15B | G19: 60.0 X 60.0 X 63.0 | H19: =VLOOKUP(G19,'Z0000002-508684 BOM triển k hai'!$G$3:$H$42,2,0) -> SPG | I19: =C19*$I$1 -> 4 | J19: =$J$1*C19 -> 24
B20: AC18 | C20: 1 | D20: KES3-12 | E20: =VLOOKUP(G20,'Z0000002-508684 BOM triển k hai'!$G$3:$R$42,12,0) -> Chốt cài KES-12 | G20: 12.0 X 3.0 X 3.0 | H20: =VLOOKUP(G20,'Z0000002-508684 BOM triển k hai'!$G$3:$H$42,2,0) -> Chốt cài | I20: =C20*$I$1 -> 4 | J20: =$J$1*C20 -> 24
B21: AC19 | C21: 8 | D21: STWN8_Misumi | E21: =VLOOKUP(G21,'Z0000002-508684 BOM triển k hai'!$G$3:$R$42,12,0) -> Phanh trục STWN8 | G21: 1.0 X 10.0 X 13.0 | H21: =VLOOKUP(G21,'Z0000002-508684 BOM triển k hai'!$G$3:$H$42,2,0) -> Phanh trục | I21: =C21*$I$1 -> 32 | J21: =$J$1*C21 -> 192
B22: AC20 | C22: 4 | D22: CV3_Pulley 1 | E22: =VLOOKUP(G22,'Z0000002-508684 BOM triển k hai'!$G$3:$R$42,12,0) -> Rulo | G22: 24.0 X 23.0 X 24.0 | H22: =VLOOKUP(G22,'Z0000002-508684 BOM triển k hai'!$G$3:$H$42,2,0) -> TT | I22: =C22*$I$1 -> 16 | J22: =$J$1*C22 -> 96
B23: AC21 | C23: 16 | D23: SB688ZZ | E23: =VLOOKUP(G23,'Z0000002-508684 BOM triển k hai'!$G$3:$R$42,12,0) -> Vòng bi SB688ZZ --> đổi sang C-SE688ZZ | G23: 16.0 X 5.0 X 16.0 | H23: =VLOOKUP(G23,'Z0000002-508684 BOM triển k hai'!$G$3:$H$42,2,0) -> VB C-SE688ZZ | I23: =C23*$I$1 -> 64 | J23: =$J$1*C23 -> 384
B24: AC22 | C24: 2 | D24: CV3_Shaft 5 | E24: =VLOOKUP(G24,'Z0000002-508684 BOM triển k hai'!$G$3:$R$42,12,0) -> SUS304, điện hóa | G24: 12.0 X 30.0 X 12.0 | H24: =VLOOKUP(G24,'Z0000002-508684 BOM triển k hai'!$G$3:$H$42,2,0) -> TT | I24: =C24*$I$1 -> 8 | J24: =$J$1*C24 -> 48
B25: AC23 | C25: 4 | D25: CV3_Pulley | E25: =VLOOKUP(G25,'Z0000002-508684 BOM triển k hai'!$G$3:$R$42,12,0) -> Rulo | G25: 21.0 X 20.0 X 21.0 | H25: =VLOOKUP(G25,'Z0000002-508684 BOM triển k hai'!$G$3:$H$42,2,0) -> TT | I25: =C25*$I$1 -> 16 | J25: =$J$1*C25 -> 96
B26: AC24 | C26: 4 | D26: CV3_Shaft 1 | E26: =VLOOKUP(G26,'Z0000002-508684 BOM triển k hai'!$G$3:$R$42,12,0) -> SUS304, điện hóa | G26: 12.0 X 29.0 X 12.0 | H26: =VLOOKUP(G26,'Z0000002-508684 BOM triển k hai'!$G$3:$H$42,2,0) -> TT | I26: =C26*$I$1 -> 16 | J26: =$J$1*C26 -> 96
B27: AC25 | C27: 2 | D27: CV3_Shaft 3 | E27: =VLOOKUP(G27,'Z0000002-508684 BOM triển k hai'!$G$3:$R$42,12,0) -> SUS304, điện hóa | G27: 12.0 X 34.0 X 12.0 | H27: =VLOOKUP(G27,'Z0000002-508684 BOM triển k hai'!$G$3:$H$42,2,0) -> TT | I27: =C27*$I$1 -> 8 | J27: =$J$1*C27 -> 48
B28: AC26 | C28: 2 | D28: CV3_AL 7 | E28: =VLOOKUP(G28,'Z0000002-508684 BOM triển k hai'!$G$3:$R$42,12,0) -> AL6061 anode đen | G28: 15.0 X 8.0 X 35.0 | H28: =VLOOKUP(G28,'Z0000002-508684 BOM triển k hai'!$G$3:$H$42,2,0) -> GTAM | I28: =C28*$I$1 -> 8 | J28: =$J$1*C28 -> 48 | K28: đã xong
B29: AC27 | C29: 2 | D29: CV3_AL 8 | E29: =VLOOKUP(G29,'Z0000002-508684 BOM triển k hai'!$G$3:$R$42,12,0) -> AL6061 anode đen | G29: 22.0 X 8.0 X 35.0 | H29: =VLOOKUP(G29,'Z0000002-508684 BOM triển k hai'!$G$3:$H$42,2,0) -> GTAM | I29: =C29*$I$1 -> 8 | J29: =$J$1*C29 -> 48 | K29: đã xong
B30: AC28 | C30: 1 | D30: CV3_Shaft 4 | E30: =VLOOKUP(G30,'Z0000002-508684 BOM triển k hai'!$G$3:$R$42,12,0) -> Trục | G30: 11.0 X 10.0 X 205.0 | H30: =VLOOKUP(G30,'Z0000002-508684 BOM triển k hai'!$G$3:$H$42,2,0) -> TT | I30: =C30*$I$1 -> 4 | J30: =$J$1*C30 -> 24
B31: AC29 | C31: 2 | D31: CV3_Pulley 2 | E31: =VLOOKUP(G31,'Z0000002-508684 BOM triển k hai'!$G$3:$R$42,12,0) -> Rulo | G31: 34.0 X 31.0 X 34.0 | H31: =VLOOKUP(G31,'Z0000002-508684 BOM triển k hai'!$G$3:$H$42,2,0) -> TT | I31: =C31*$I$1 -> 8 | J31: =$J$1*C31 -> 48
B32: AC30 | C32: 2 | D32: SB6000ZZ | E32: =VLOOKUP(G32,'Z0000002-508684 BOM triển k hai'!$G$3:$R$42,12,0) -> Vòng bi SB6000ZZ --> đổi sang C-SE6000ZZ | G32: 26.0 X 8.0 X 26.0 | H32: =VLOOKUP(G32,'Z0000002-508684 BOM triển k hai'!$G$3:$H$42,2,0) -> VB C-SE6000ZZ | I32: =C32*$I$1 -> 8 | J32: =$J$1*C32 -> 48
B33: AC31 | C33: 2 | D33: STWN10 | E33: =VLOOKUP(G33,'Z0000002-508684 BOM triển k hai'!$G$3:$R$42,12,0) -> phanh trục STWN10 | G33: 1.0 X 15.0 X 13.0 | H33: =VLOOKUP(G33,'Z0000002-508684 BOM triển k hai'!$G$3:$H$42,2,0) -> Phanh trục | I33: =C33*$I$1 -> 8 | J33: =$J$1*C33 -> 48
B34: AC32 | C34: 1 | D34: HTPA18S5M100-B-N10-FC30.0_Misumi | E34: =VLOOKUP(G34,'Z0000002-508684 BOM triển k hai'!$G$3:$R$42,12,0) -> HTPA18S5M100-B-N10-FC30.0 đổi sang HTPA18S5M150-B-N10-FC30.0 | G34: 28.0 X 30.0 X 30.0 | H34: =VLOOKUP(G34,'Z0000002-508684 BOM triển k hai'!$G$3:$H$42,2,0) -> UP | I34: =C34*$I$1 -> 4 | J34: =$J$1*C34 -> 24
B35: AC33 | C35: 3 | D35: KES3-15 | E35: =VLOOKUP(G35,'Z0000002-508684 BOM triển k hai'!$G$3:$R$42,12,0) -> Chốt cài KES-15 | G35: 15.0 X 3.0 X 3.0 | H35: =VLOOKUP(G35,'Z0000002-508684 BOM triển k hai'!$G$3:$H$42,2,0) -> Chốt cài | I35: =C35*$I$1 -> 12 | J35: =$J$1*C35 -> 72
B36: AC34 | C36: 1 | D36: MF_Al6061_1323 | E36: =E28 -> AL6061 anode đen | G36: 36.0 X 10.0 X 65.0 | H36: =H28 -> GTAM | I36: =C36*$I$1 -> 4 | J36: =$J$1*C36 -> 24 | K36: đã xong
B37: AC35 | C37: 1 | D37: MF_Al6061_1021 | E37: =E36 -> AL6061 anode đen | G37: 32.0 X 7.0 X 50.0 | H37: =H36 -> GTAM | I37: =C37*$I$1 -> 4 | J37: =$J$1*C37 -> 24 | K37: chưa gc
B38: AC36 | C38: 1 | D38: MF_Al6061_1325 | E38: =E37 -> AL6061 anode đen | G38: 60.0 X 10.0 X 20.0 | H38: =H37 -> GTAM | I38: =C38*$I$1 -> 4 | J38: =$J$1*C38 -> 24 | K38: đã xong
H40: ='Z0000002-508684 BOM triển k hai'!H45 -> Belt | I40: ='Z0000002-508684 BOM triển k hai'!I45 -> đã nhận đủ hàng 9/4 | J40: ='Z0000002-508684 BOM triển k hai'!J45 -> đã đặt hàng 10/4, hẹn 25/4 giao 50%, 5/5 giao nốt
H41: ='Z0000002-508684 BOM triển k hai'!H46 -> CG | I41: ='Z0000002-508684 BOM triển k hai'!I46 -> đã xong 9/4 | J41: ='Z0000002-508684 BOM triển k hai'!J46 -> 0
...

Sheet Z0000002-508701 BOM triển k hai
A1: CONVEYOR_Z0000002-508701_ Code_Conveyor Transfer - BOM | H1: SL | I1: 2 | J1: ='[1]ducpt trien khai'!$I$29 -> 12
A2: Image | B2: ID Number | C2: Quantity | D2: Standard Number | E2: Sub Category | F2: Category | G2: Visible Part Size | H2: ='Z0000002-508700 BOM triển k hai'!H2 -> NCC/vật tư | I2: SL
B3: AD01 | C3: 1 | D3: CV3_AL 3_UV 6234 | E3: AL6061 anode đen | G3: 395.0 X 200.0 X 12.0 | H3: GTAM | I3: =C3*$I$1 -> 2 | J3: =$J$1*C3 -> 12 | K3: đã xong
B4: AD02 | C4: 1 | D4: MF_PB108 Black_56 | E4: =VLOOKUP(G4,'Z0000002-508684 BOM triển k hai'!$G$3:$R$42,12,0) -> PB108 | G4: 395.0 X 19.0 X 10.0 | H4: =VLOOKUP(G4,'Z0000002-508684 BOM triển k hai'!$G$3:$H$42,2,0) -> GTAM | I4: =C4*$I$1 -> 2 | J4: =$J$1*C4 -> 12 | K4: xong nc1
B5: AD03 | C5: 1 | D5: MF_PB108 Black_57 | E5: =VLOOKUP(G5,'Z0000002-508684 BOM triển k hai'!$G$3:$R$42,12,0) -> PB108 | G5: 395.0 X 19.0 X 10.0 | H5: =VLOOKUP(G5,'Z0000002-508684 BOM triển k hai'!$G$3:$H$42,2,0) -> GTAM | I5: =C5*$I$1 -> 2 | J5: =$J$1*C5 -> 12 | K5: xong nc1
B6: AD04 | C6: 1 | D6: MF_SUS304_0213 | E6: SUS304, điện hóa | G6: 20.0 X 50.0 X 21.0 | H6: CG | I6: =C6*$I$1 -> 2 | J6: =$J$1*C6 -> 12
B7: AD05 | C7: 1 | D7: MF_SUS304_1244 | E7: =VLOOKUP(G7,'Z0000002-508684 BOM triển k hai'!$G$3:$R$42,12,0) -> SUS304, điện hóa | G7: 25.0 X 53.0 X 51.0 | H7: =VLOOKUP(G7,'Z0000002-508684 BOM triển k hai'!$G$3:$H$42,2,0) -> CG | I7: =C7*$I$1 -> 2 | J7: =$J$1*C7 -> 12
B8: AD06 | C8: 1 | D8: MF_SUS304_0212 | E8: =E7 -> SUS304, điện hóa | G8: 20.0 X 50.0 X 21.0 | H8: =H7 -> CG | I8: =C8*$I$1 -> 2 | J8: =$J$1*C8 -> 12
B9: AD07 | C9: 1 | D9: MF_SUS204_1234 | E9: =VLOOKUP(G9,'Z0000002-508684 BOM triển k hai'!$G$3:$R$42,12,0) -> SUS304, điện hóa | G9: 25.0 X 63.0 X 56.0 | H9: =VLOOKUP(G9,'Z0000002-508684 BOM triển k hai'!$G$3:$H$42,2,0) -> CG | I9: =C9*$I$1 -> 2 | J9: =$J$1*C9 -> 12
B10: AD08 | C10: 1 | D10: CV3_AL 2 _UV_MIR | E10: =VLOOKUP(G10,'Z0000002-508684 BOM triển k hai'!$G$3:$R$42,12,0) -> AL6061 anode đen | G10: 395.0 X 12.0 X 89.0 | H10: =VLOOKUP(G10,'Z0000002-508684 BOM triển k hai'!$G$3:$H$42,2,0) -> GTAM | I10: =C10*$I$1 -> 2 | J10: =$J$1*C10 -> 12 | K10: đã xong
B11: AD09 | C11: 1 | D11: CV3_AL 9 uv | E11: =VLOOKUP(G11,'Z0000002-508684 BOM triển k hai'!$G$3:$R$42,12,0) -> AL6061 anode đen | G11: 60.0 X 20.0 X 63.0 | H11: =VLOOKUP(G11,'Z0000002-508684 BOM triển k hai'!$G$3:$H$42,2,0) -> GTAM | I11: =C11*$I$1 -> 2 | J11: =$J$1*C11 -> 12 | K11: đã xong
B12: AD10 | C12: 1 | D12: HTPA18S5M100-A-N8-FC30.0 | E12: =VLOOKUP(G12,'Z0000002-508684 BOM triển k hai'!$G$3:$R$42,12,0) -> HTPA18S5M100-A-N8-FC30.0 đổi sang HTPA18S5M150-A-N8-FC30.0 | G12: 31.0 X 16.0 X 31.0 | H12: =VLOOKUP(G12,'Z0000002-508684 BOM triển k hai'!$G$3:$H$42,2,0) -> UP | I12: =C12*$I$1 -> 2 | J12: =$J$1*C12 -> 12
B13: AD11 | C13: 1 | D13: CV3_AL 10. | E13: =VLOOKUP(G13,'Z0000002-508684 BOM triển k hai'!$G$3:$R$42,12,0) -> AL6061 anode đen | G13: 15.0 X 8.0 X 35.0 | H13: =VLOOKUP(G13,'Z0000002-508684 BOM triển k hai'!$G$3:$H$42,2,0) -> GTAM | I13: =C13*$I$1 -> 2 | J13: =$J$1*C13 -> 12 | K13: đã xong
B14: AD12 | C14: 1 | D14: TTBU250T5-100_info-1-18-18_1 | E14: =VLOOKUP(G14,'Z0000002-508684 BOM triển k hai'!$G$3:$R$42,12,0) -> TTBU250T5-100 --> đổi sang C-TTBN250T5-150 | G14: 110.0 X 30.0 X 10.0 | H14: =VLOOKUP(G14,'Z0000002-508684 BOM triển k hai'!$G$3:$H$42,2,0) -> MI | I14: =C14*$I$1 -> 2 | J14: =$J$1*C14 -> 12
B15: AD13 | C15: 2 | D15: CV3_Belt 1_UV | E15: =VLOOKUP(G15,'Z0000002-508684 BOM triển k hai'!$G$3:$R$42,12,0) -> belt PU đen, chống tĩnh điện, ép viền chống xước, dày 1.5mm, bản rộng 20mm, chu vi 890mm( đo mép trong 895mm, chốt cân chỉnh đang ở giữa ) | G15: 394.0 X 20.0 X 80.0 | H15: =VLOOKUP(G15,'Z0000002-508684 BOM triển k hai'!$G$3:$H$42,2,0) -> Belt | I15: =C15*$I$1 -> 4 | J15: =$J$1*C15 -> 24
B16: AD14 | C16: 2 | D16: CV3_Pb108-1_UV | E16: =VLOOKUP(G16,'Z0000002-508684 BOM triển k hai'!$G$3:$R$42,12,0) -> PB108 | G16: 344.0 X 26.0 X 16.0 | H16: =VLOOKUP(G16,'Z0000002-508684 BOM triển k hai'!$G$3:$H$42,2,0) -> GTAM | I16: =C16*$I$1 -> 4 | J16: =$J$1*C16 -> 24 | K16: chưa gc
B17: AD15 | C17: 1 | D17: CV3_AL 2 _UV | E17: =VLOOKUP(G17,'Z0000002-508684 BOM triển k hai'!$G$3:$R$42,12,0) -> AL6061 anode đen | G17: 395.0 X 12.0 X 89.0 | H17: =VLOOKUP(G17,'Z0000002-508684 BOM triển k hai'!$G$3:$H$42,2,0) -> GTAM | I17: =C17*$I$1 -> 2 | J17: =$J$1*C17 -> 12 | K17: đã xong
B18: AD16 | C18: 1 | D18: MF_Al6061_841 | E18: =VLOOKUP(G18,'Z0000002-508684 BOM triển k hai'!$G$3:$R$42,12,0) -> AL6061 anode đen | G18: 10.0 X 70.0 X 70.0 | H18: =VLOOKUP(G18,'Z0000002-508684 BOM triển k hai'!$G$3:$H$42,2,0) -> GTAM | I18: =C18*$I$1 -> 2 | J18: =$J$1*C18 -> 12 | K18: đã xong
B19: AD17 | C19: 1 | D19: MF_Al6061_845 | E19: =VLOOKUP(G19,'Z0000002-508684 BOM triển k hai'!$G$3:$R$42,12,0) -> AL6061 anode đen | G19: 16.0 X 25.0 X 62.0 | H19: =VLOOKUP(G19,'Z0000002-508684 BOM triển k hai'!$G$3:$H$42,2,0) -> GTAM | I19: =C19*$I$1 -> 2 | J19: =$J$1*C19 -> 12 | K19: chưa gc
B20: AD18 | C20: 1 | D20: MF_Urethan 90_1119 | E20: =VLOOKUP(G20,'Z0000002-508684 BOM triển k hai'!$G$3:$R$42,12,0) -> AL6061 anode đen | G20: 15.0 X 8.0 X 35.0 | H20: =VLOOKUP(G20,'Z0000002-508684 BOM triển k hai'!$G$3:$H$42,2,0) -> GTAM | I20: =C20*$I$1 -> 2 | J20: =$J$1*C20 -> 12 | K20: chưa gc
B21: AD19 | C21: 1 | D21: S6I06G-GX | E21: =VLOOKUP(G21,'Z0000002-508684 BOM triển k hai'!$G$3:$R$42,12,0) -> S6I06GX-12CE và bộ đk tốc độ SUA06IX-V12 | G21: 100.0 X 60.0 X 62.0 | H21: =VLOOKUP(G21,'Z0000002-508684 BOM triển k hai'!$G$3:$H$42,2,0) -> SPG | I21: =C21*$I$1 -> 2 | J21: =$J$1*C21 -> 12 | K21: ='Z0000002-508684 BOM triển k hai'!K18 -> NG báo đã nhận 27 set, đủ lô 7CV
B22: AD20 | C22: 1 | D22: S6KA3-15 | E22: =VLOOKUP(G22,'Z0000002-508684 BOM triển k hai'!$G$3:$R$42,12,0) -> hộp số S6KA15B | G22: 60.0 X 60.0 X 63.0 | H22: =VLOOKUP(G22,'Z0000002-508684 BOM triển k hai'!$G$3:$H$42,2,0) -> SPG | I22: =C22*$I$1 -> 2 | J22: =$J$1*C22 -> 12 | K22: =K21 -> NG báo đã nhận 27 set, đủ lô 7CV
B23: AD21 | C23: 1 | D23: KES3-12 | E23: =VLOOKUP(G23,'Z0000002-508684 BOM triển k hai'!$G$3:$R$42,12,0) -> Chốt cài KES-12 | G23: 12.0 X 3.0 X 3.0 | H23: =VLOOKUP(G23,'Z0000002-508684 BOM triển k hai'!$G$3:$H$42,2,0) -> Chốt cài | I23: =C23*$I$1 -> 2 | J23: =$J$1*C23 -> 12
B24: AD22 | C24: 8 | D24: STWN8_Misumi | E24: =VLOOKUP(G24,'Z0000002-508684 BOM triển k hai'!$G$3:$R$42,12,0) -> Phanh trục STWN8 | G24: 1.0 X 10.0 X 13.0 | H24: =VLOOKUP(G24,'Z0000002-508684 BOM triển k hai'!$G$3:$H$42,2,0) -> Phanh trục | I24: =C24*$I$1 -> 16 | J24: =$J$1*C24 -> 96
B25: AD23 | C25: 4 | D25: CV3_Pulley 1 | E25: =VLOOKUP(G25,'Z0000002-508684 BOM triển k hai'!$G$3:$R$42,12,0) -> Rulo | G25: 24.0 X 23.0 X 24.0 | H25: =VLOOKUP(G25,'Z0000002-508684 BOM triển k hai'!$G$3:$H$42,2,0) -> TT | I25: =C25*$I$1 -> 8 | J25: =$J$1*C25 -> 48
B26: AD24 | C26: 16 | D26: SB688ZZ | E26: =VLOOKUP(G26,'Z0000002-508684 BOM triển k hai'!$G$3:$R$42,12,0) -> Vòng bi SB688ZZ --> đổi sang C-SE688ZZ | G26: 16.0 X 5.0 X 16.0 | H26: =VLOOKUP(G26,'Z0000002-508684 BOM triển k hai'!$G$3:$H$42,2,0) -> VB C-SE688ZZ | I26: =C26*$I$1 -> 32 | J26: =$J$1*C26 -> 192
B27: AD25 | C27: 2 | D27: CV3_Shaft 5 | E27: =VLOOKUP(G27,'Z0000002-508684 BOM triển k hai'!$G$3:$R$42,12,0) -> SUS304, điện hóa | G27: 12.0 X 30.0 X 12.0 | H27: =VLOOKUP(G27,'Z0000002-508684 BOM triển k hai'!$G$3:$H$42,2,0) -> TT | I27: =C27*$I$1 -> 4 | J27: =$J$1*C27 -> 24
B28: AD26 | C28: 4 | D28: CV3_Pulley | E28: =VLOOKUP(G28,'Z0000002-508684 BOM triển k hai'!$G$3:$R$42,12,0) -> Rulo | G28: 21.0 X 20.0 X 21.0 | H28: =VLOOKUP(G28,'Z0000002-508684 BOM triển k hai'!$G$3:$H$42,2,0) -> TT | I28: =C28*$I$1 -> 8 | J28: =$J$1*C28 -> 48
B29: AD27 | C29: 4 | D29: CV3_Shaft 1 | E29: =VLOOKUP(G29,'Z0000002-508684 BOM triển k hai'!$G$3:$R$42,12,0) -> SUS304, điện hóa | G29: 12.0 X 29.0 X 12.0 | H29: =VLOOKUP(G29,'Z0000002-508684 BOM triển k hai'!$G$3:$H$42,2,0) -> TT | I29: =C29*$I$1 -> 8 | J29: =$J$1*C29 -> 48
B30: AD28 | C30: 2 | D30: CV3_Shaft 3 | E30: =VLOOKUP(G30,'Z0000002-508684 BOM triển k hai'!$G$3:$R$42,12,0) -> SUS304, điện hóa | G30: 12.0 X 34.0 X 12.0 | H30: =VLOOKUP(G30,'Z0000002-508684 BOM triển k hai'!$G$3:$H$42,2,0) -> TT | I30: =C30*$I$1 -> 4 | J30: =$J$1*C30 -> 24
B31: AD29 | C31: 2 | D31: CV3_AL 7 | E31: =VLOOKUP(G31,'Z0000002-508684 BOM triển k hai'!$G$3:$R$42,12,0) -> AL6061 anode đen | G31: 15.0 X 8.0 X 35.0 | H31: =VLOOKUP(G31,'Z0000002-508684 BOM triển k hai'!$G$3:$H$42,2,0) -> GTAM | I31: =C31*$I$1 -> 4 | J31: =$J$1*C31 -> 24 | K31: đã xong
B32: AD30 | C32: 2 | D32: CV3_AL 8 | E32: =VLOOKUP(G32,'Z0000002-508684 BOM triển k hai'!$G$3:$R$42,12,0) -> AL6061 anode đen | G32: 22.0 X 8.0 X 35.0 | H32: =VLOOKUP(G32,'Z0000002-508684 BOM triển k hai'!$G$3:$H$42,2,0) -> GTAM | I32: =C32*$I$1 -> 4 | J32: =$J$1*C32 -> 24 | K32: đã xong
B33: AD31 | C33: 1 | D33: CV3_Shaft 4 | E33: =VLOOKUP(G33,'Z0000002-508684 BOM triển k hai'!$G$3:$R$42,12,0) -> Trục | G33: 11.0 X 10.0 X 205.0 | H33: =VLOOKUP(G33,'Z0000002-508684 BOM triển k hai'!$G$3:$H$42,2,0) -> TT | I33: =C33*$I$1 -> 2 | J33: =$J$1*C33 -> 12
B34: AD32 | C34: 2 | D34: CV3_Pulley 2 | E34: =VLOOKUP(G34,'Z0000002-508684 BOM triển k hai'!$G$3:$R$42,12,0) -> Rulo | G34: 34.0 X 31.0 X 34.0 | H34: =VLOOKUP(G34,'Z0000002-508684 BOM triển k hai'!$G$3:$H$42,2,0) -> TT | I34: =C34*$I$1 -> 4 | J34: =$J$1*C34 -> 24
B35: AD33 | C35: 2 | D35: SB6000ZZ | E35: =VLOOKUP(G35,'Z0000002-508684 BOM triển k hai'!$G$3:$R$42,12,0) -> Vòng bi SB6000ZZ --> đổi sang C-SE6000ZZ | G35: 26.0 X 8.0 X 26.0 | H35: =VLOOKUP(G35,'Z0000002-508684 BOM triển k hai'!$G$3:$H$42,2,0) -> VB C-SE6000ZZ | I35: =C35*$I$1 -> 4 | J35: =$J$1*C35 -> 24
B36: AD34 | C36: 2 | D36: STWN10 | E36: =VLOOKUP(G36,'Z0000002-508684 BOM triển k hai'!$G$3:$R$42,12,0) -> phanh trục STWN10 | G36: 1.0 X 15.0 X 13.0 | H36: =VLOOKUP(G36,'Z0000002-508684 BOM triển k hai'!$G$3:$H$42,2,0) -> Phanh trục | I36: =C36*$I$1 -> 4 | J36: =$J$1*C36 -> 24
B37: AD35 | C37: 1 | D37: HTPA18S5M100-B-N10-FC30.0_Misumi | E37: =VLOOKUP(G37,'Z0000002-508684 BOM triển k hai'!$G$3:$R$42,12,0) -> HTPA18S5M100-B-N10-FC30.0 đổi sang HTPA18S5M150-B-N10-FC30.0 | G37: 28.0 X 30.0 X 30.0 | H37: =VLOOKUP(G37,'Z0000002-508684 BOM triển k hai'!$G$3:$H$42,2,0) -> UP | I37: =C37*$I$1 -> 2 | J37: =$J$1*C37 -> 12
B38: AD36 | C38: 3 | D38: KES3-15 | E38: =VLOOKUP(G38,'Z0000002-508684 BOM triển k hai'!$G$3:$R$42,12,0) -> Chốt cài KES-15 | G38: 15.0 X 3.0 X 3.0 | H38: =VLOOKUP(G38,'Z0000002-508684 BOM triển k hai'!$G$3:$H$42,2,0) -> Chốt cài | I38: =C38*$I$1 -> 6 | J38: =$J$1*C38 -> 36
H40: ='Z0000002-508684 BOM triển k hai'!H45 -> Belt | I40: ='Z0000002-508684 BOM triển k hai'!I45 -> đã nhận đủ hàng 9/4 | J40: ='Z0000002-508684 BOM triển k hai'!J45 -> đã đặt hàng 10/4, hẹn 25/4 giao 50%, 5/5 giao nốt | K40: ='Z0000002-508684 BOM triển k hai'!K45 -> 0
H41: ='Z0000002-508684 BOM triển k hai'!H46 -> CG | I41: ='Z0000002-508684 BOM triển k hai'!I46 -> đã xong 9/4 | J41: ='Z0000002-508684 BOM triển k hai'!J46 -> 0 | K41: ='Z0000002-508684 BOM triển k hai'!K46 -> 0
...

Sheet Z0000002-508703 BOM triển khai
A1: CONVEYOR_Z0000002-508703_ Code_Conveyor_Shutter_1 - BOM | H1: SL | I1: 2 | J1: ='[1]ducpt trien khai'!$I$30 -> 12
A2: Image | B2: ID Number | C2: Quantity | D2: Standard Number | E2: Sub Category | F2: Category | G2: Visible Part Size | H2: ='Z0000002-508700 BOM triển k hai'!H2 -> NCC/vật tư | I2: SL | K2: note 1
B3: AE01 | C3: 1 | D3: MF_SUS304_1244 | E3: =VLOOKUP(G3,'Z0000002-508684 BOM triển k hai'!$G$3:$R$42,12,0) -> SUS304, điện hóa | G3: 25.0 X 53.0 X 51.0 | H3: =VLOOKUP(G3,'Z0000002-508684 BOM triển k hai'!$G$3:$H$42,2,0) -> CG | I3: =$I$1*C3 -> 2 | J3: =$J$1*C3 -> 12
B4: AE02 | C4: 1 | D4: MF_SUS204_1143 | E4: =VLOOKUP(G4,'Z0000002-508684 BOM triển k hai'!$G$3:$R$42,12,0) -> SUS304, điện hóa | G4: 25.0 X 63.0 X 56.0 | H4: =VLOOKUP(G4,'Z0000002-508684 BOM triển k hai'!$G$3:$H$42,2,0) -> CG | I4: =$I$1*C4 -> 2 | J4: =$J$1*C4 -> 12
B5: AE03 | C5: 1 | D5: MF_SUS304_0210_1456 MIR | E5: =E4 -> SUS304, điện hóa | G5: 20.0 X 50.0 X 21.0 | H5: =H4 -> CG | I5: =$I$1*C5 -> 2 | J5: =$J$1*C5 -> 12
B6: AE04 | C6: 1 | D6: MF_SUS304_0210_1456 | E6: =E5 -> SUS304, điện hóa | G6: 20.0 X 50.0 X 21.0 | H6: =H5 -> CG | I6: =$I$1*C6 -> 2 | J6: =$J$1*C6 -> 12
B7: AE05 | C7: 1 | D7: TTBU250T5-100_info-1-18-18_1 | E7: =VLOOKUP(G7,'Z0000002-508684 BOM triển k hai'!$G$3:$R$42,12,0) -> TTBU250T5-100 --> đổi sang C-TTBN250T5-150 | G7: 110.0 X 30.0 X 10.0 | H7: =VLOOKUP(G7,'Z0000002-508684 BOM triển k hai'!$G$3:$H$42,2,0) -> MI | I7: =$I$1*C7 -> 2 | J7: =$J$1*C7 -> 12
B8: AE06 | C8: 2 | D8: MF_Aluminum 6061_0202_2087 | E8: =VLOOKUP(G8,'Z0000002-508684 BOM triển k hai'!$G$3:$R$42,12,0) -> AL6061 anode đen | G8: 60.0 X 12.0 X 10.0 | H8: =VLOOKUP(G8,'Z0000002-508684 BOM triển k hai'!$G$3:$H$42,2,0) -> GTAM | I8: =$I$1*C8 -> 4 | J8: =$J$1*C8 -> 24 | K8: đã xong
B9: AE07 | C9: 2 | D9: MF_Aluminum 6061_0202_1 | E9: =E8 -> AL6061 anode đen | G9: 120.0 X 61.0 X 20.0 | H9: =H8 -> GTAM | I9: =$I$1*C9 -> 4 | J9: =$J$1*C9 -> 24 | K9: chưa gc
B10: AE08 | C10: 1 | D10: MF_Aluminum 6061_0202_1854 | E10: =E9 -> AL6061 anode đen | G10: 220.0 X 152.0 X 10.0 | H10: =H9 -> GTAM | I10: =$I$1*C10 -> 2 | J10: =$J$1*C10 -> 12 | K10: đã xong
B11: AE09 | C11: 1 | D11: CV3_Pb108_Shutter_MIR | E11: =VLOOKUP(G11,'Z0000002-508684 BOM triển k hai'!$G$3:$R$42,12,0) -> PB108 | G11: 395.0 X 19.0 X 10.0 | H11: =VLOOKUP(G11,'Z0000002-508684 BOM triển k hai'!$G$3:$H$42,2,0) -> GTAM | I11: =$I$1*C11 -> 2 | J11: =$J$1*C11 -> 12 | K11: xong nc1
B12: AE10 | C12: 1 | D12: CV3_Pb108_Shutter | E12: =VLOOKUP(G12,'Z0000002-508684 BOM triển k hai'!$G$3:$R$42,12,0) -> PB108 | G12: 395.0 X 19.0 X 10.0 | H12: =VLOOKUP(G12,'Z0000002-508684 BOM triển k hai'!$G$3:$H$42,2,0) -> GTAM | I12: =$I$1*C12 -> 2 | J12: =$J$1*C12 -> 12 | K12: xong nc1
B13: AE11 | C13: 2 | D13: CV3_Pb108-1_UV | E13: =VLOOKUP(G13,'Z0000002-508684 BOM triển k hai'!$G$3:$R$42,12,0) -> PB108 | G13: 344.0 X 26.0 X 16.0 | H13: =VLOOKUP(G13,'Z0000002-508684 BOM triển k hai'!$G$3:$H$42,2,0) -> GTAM | I13: =$I$1*C13 -> 4 | J13: =$J$1*C13 -> 24 | K13: chưa gc
B14: AE12 | C14: 2 | D14: CV3_Belt 1_UV | E14: =VLOOKUP(G14,'Z0000002-508684 BOM triển k hai'!$G$3:$R$42,12,0) -> belt PU đen, chống tĩnh điện, ép viền chống xước, dày 1.5mm, bản rộng 20mm, chu vi 890mm( đo mép trong 895mm, chốt cân chỉnh đang ở giữa ) | G14: 394.0 X 20.0 X 80.0 | H14: =VLOOKUP(G14,'Z0000002-508684 BOM triển k hai'!$G$3:$H$42,2,0) -> Belt | I14: =$I$1*C14 -> 4 | J14: =$J$1*C14 -> 24
B15: AE13 | C15: 1 | D15: CV3_AL_Shutter | E15: =VLOOKUP(G15,'Z0000002-508684 BOM triển k hai'!$G$3:$R$42,12,0) -> AL6061 anode đen | G15: 395.0 X 12.0 X 89.0 | H15: =VLOOKUP(G15,'Z0000002-508684 BOM triển k hai'!$G$3:$H$42,2,0) -> GTAM | I15: =$I$1*C15 -> 2 | J15: =$J$1*C15 -> 12 | K15: đã xong
B16: AE14 | C16: 1 | D16: CV3_AL_Shutter MIR | E16: =VLOOKUP(G16,'Z0000002-508684 BOM triển k hai'!$G$3:$R$42,12,0) -> AL6061 anode đen | G16: 395.0 X 12.0 X 89.0 | H16: =VLOOKUP(G16,'Z0000002-508684 BOM triển k hai'!$G$3:$H$42,2,0) -> GTAM | I16: =$I$1*C16 -> 2 | J16: =$J$1*C16 -> 12 | K16: đã xong
B17: AE15 | C17: 1 | D17: CV3_AL 32_Shutter_1 | E17: =VLOOKUP(G17,'Z0000002-508684 BOM triển k hai'!$G$3:$R$42,12,0) -> #N/A | G17: 395.0 X 200.0 X 12.0 | H17: =H16 -> GTAM | I17: =$I$1*C17 -> 2 | J17: =$J$1*C17 -> 12 | K17: đã xong
B18: AE16 | C18: 1 | D18: CV3_AL 9 Shutter 1 | E18: =VLOOKUP(G18,'Z0000002-508684 BOM triển k hai'!$G$3:$R$42,12,0) -> AL6061 anode đen | G18: 60.0 X 20.0 X 63.0 | H18: =VLOOKUP(G18,'Z0000002-508684 BOM triển k hai'!$G$3:$H$42,2,0) -> GTAM | I18: =$I$1*C18 -> 2 | J18: =$J$1*C18 -> 12 | K18: đã xong
B19: AE17 | C19: 1 | D19: HTPA18S5M100-A-N8-FC30.0 | E19: =VLOOKUP(G19,'Z0000002-508684 BOM triển k hai'!$G$3:$R$42,12,0) -> HTPA18S5M100-A-N8-FC30.0 đổi sang HTPA18S5M150-A-N8-FC30.0 | G19: 31.0 X 16.0 X 31.0 | H19: =VLOOKUP(G19,'Z0000002-508684 BOM triển k hai'!$G$3:$H$42,2,0) -> UP | I19: =$I$1*C19 -> 2 | J19: =$J$1*C19 -> 12
B20: AE18 | C20: 1 | D20: CV3_AL 10. | E20: =VLOOKUP(G20,'Z0000002-508684 BOM triển k hai'!$G$3:$R$42,12,0) -> AL6061 anode đen | G20: 15.0 X 8.0 X 35.0 | H20: =VLOOKUP(G20,'Z0000002-508684 BOM triển k hai'!$G$3:$H$42,2,0) -> GTAM | I20: =$I$1*C20 -> 2 | J20: =$J$1*C20 -> 12 | K20: đã xong
B21: AE19 | C21: 1 | D21: MF_Al6061_841 | E21: =VLOOKUP(G21,'Z0000002-508684 BOM triển k hai'!$G$3:$R$42,12,0) -> AL6061 anode đen | G21: 10.0 X 70.0 X 70.0 | H21: =VLOOKUP(G21,'Z0000002-508684 BOM triển k hai'!$G$3:$H$42,2,0) -> GTAM | I21: =$I$1*C21 -> 2 | J21: =$J$1*C21 -> 12 | K21: đã xong
B22: AE20 | C22: 1 | D22: MF_Al6061_845 | E22: =VLOOKUP(G22,'Z0000002-508684 BOM triển k hai'!$G$3:$R$42,12,0) -> AL6061 anode đen | G22: 16.0 X 25.0 X 62.0 | H22: =VLOOKUP(G22,'Z0000002-508684 BOM triển k hai'!$G$3:$H$42,2,0) -> GTAM | I22: =$I$1*C22 -> 2 | J22: =$J$1*C22 -> 12
B23: AE21 | C23: 1 | D23: MF_Urethan 90_1119 | E23: =VLOOKUP(G23,'Z0000002-508684 BOM triển k hai'!$G$3:$R$42,12,0) -> AL6061 anode đen | G23: 15.0 X 8.0 X 35.0 | H23: =VLOOKUP(G23,'Z0000002-508684 BOM triển k hai'!$G$3:$H$42,2,0) -> GTAM | I23: =$I$1*C23 -> 2 | J23: =$J$1*C23 -> 12 | K23: chưa gc
B24: AE22 | C24: 1 | D24: S6I06G-GX | E24: =VLOOKUP(G24,'Z0000002-508684 BOM triển k hai'!$G$3:$R$42,12,0) -> S6I06GX-12CE và bộ đk tốc độ SUA06IX-V12 | G24: 100.0 X 60.0 X 62.0 | H24: =VLOOKUP(G24,'Z0000002-508684 BOM triển k hai'!$G$3:$H$42,2,0) -> SPG | I24: =$I$1*C24 -> 2 | J24: =$J$1*C24 -> 12 | K24: ='Z0000002-508701 BOM triển k hai'!K21 -> NG báo đã nhận 27 set, đủ lô 7CV
B25: AE23 | C25: 1 | D25: S6KA3-15 | E25: =VLOOKUP(G25,'Z0000002-508684 BOM triển k hai'!$G$3:$R$42,12,0) -> hộp số S6KA15B | G25: 60.0 X 60.0 X 63.0 | H25: =VLOOKUP(G25,'Z0000002-508684 BOM triển k hai'!$G$3:$H$42,2,0) -> SPG | I25: =$I$1*C25 -> 2 | J25: =$J$1*C25 -> 12 | K25: =K24 -> NG báo đã nhận 27 set, đủ lô 7CV
B26: AE24 | C26: 1 | D26: KES3-12 | E26: =VLOOKUP(G26,'Z0000002-508684 BOM triển k hai'!$G$3:$R$42,12,0) -> Chốt cài KES-12 | G26: 12.0 X 3.0 X 3.0 | H26: =VLOOKUP(G26,'Z0000002-508684 BOM triển k hai'!$G$3:$H$42,2,0) -> Chốt cài | I26: =$I$1*C26 -> 2 | J26: =$J$1*C26 -> 12
B27: AE25 | C27: 4 | D27: CV3_Pulley 1 | E27: =VLOOKUP(G27,'Z0000002-508684 BOM triển k hai'!$G$3:$R$42,12,0) -> Rulo | G27: 24.0 X 23.0 X 24.0 | H27: =VLOOKUP(G27,'Z0000002-508684 BOM triển k hai'!$G$3:$H$42,2,0) -> TT | I27: =$I$1*C27 -> 8 | J27: =$J$1*C27 -> 48
B28: AE26 | C28: 16 | D28: SB688ZZ | E28: =VLOOKUP(G28,'Z0000002-508684 BOM triển k hai'!$G$3:$R$42,12,0) -> Vòng bi SB688ZZ --> đổi sang C-SE688ZZ | G28: 16.0 X 5.0 X 16.0 | H28: =VLOOKUP(G28,'Z0000002-508684 BOM triển k hai'!$G$3:$H$42,2,0) -> VB C-SE688ZZ | I28: =$I$1*C28 -> 32 | J28: =$J$1*C28 -> 192
B29: AE27 | C29: 2 | D29: CV3_Shaft 5 | E29: =VLOOKUP(G29,'Z0000002-508684 BOM triển k hai'!$G$3:$R$42,12,0) -> SUS304, điện hóa | G29: 12.0 X 30.0 X 12.0 | H29: =VLOOKUP(G29,'Z0000002-508684 BOM triển k hai'!$G$3:$H$42,2,0) -> TT | I29: =$I$1*C29 -> 4 | J29: =$J$1*C29 -> 24
B30: AE28 | C30: 8 | D30: STWN8_Misumi | E30: =VLOOKUP(G30,'Z0000002-508684 BOM triển k hai'!$G$3:$R$42,12,0) -> Phanh trục STWN8 | G30: 1.0 X 10.0 X 13.0 | H30: =VLOOKUP(G30,'Z0000002-508684 BOM triển k hai'!$G$3:$H$42,2,0) -> Phanh trục | I30: =$I$1*C30 -> 16 | J30: =$J$1*C30 -> 96
B31: AE29 | C31: 4 | D31: CV3_Pulley | E31: =VLOOKUP(G31,'Z0000002-508684 BOM triển k hai'!$G$3:$R$42,12,0) -> Rulo | G31: 21.0 X 20.0 X 21.0 | H31: =VLOOKUP(G31,'Z0000002-508684 BOM triển k hai'!$G$3:$H$42,2,0) -> TT | I31: =$I$1*C31 -> 8 | J31: =$J$1*C31 -> 48
B32: AE30 | C32: 4 | D32: CV3_Shaft 1 | E32: =VLOOKUP(G32,'Z0000002-508684 BOM triển k hai'!$G$3:$R$42,12,0) -> SUS304, điện hóa | G32: 12.0 X 29.0 X 12.0 | H32: =VLOOKUP(G32,'Z0000002-508684 BOM triển k hai'!$G$3:$H$42,2,0) -> TT | I32: =$I$1*C32 -> 8 | J32: =$J$1*C32 -> 48
B33: AE31 | C33: 1 | D33: CV3_Shaft 4 | E33: =VLOOKUP(G33,'Z0000002-508684 BOM triển k hai'!$G$3:$R$42,12,0) -> Trục | G33: 11.0 X 10.0 X 205.0 | H33: =VLOOKUP(G33,'Z0000002-508684 BOM triển k hai'!$G$3:$H$42,2,0) -> TT | I33: =$I$1*C33 -> 2 | J33: =$J$1*C33 -> 12
B34: AE32 | C34: 2 | D34: CV3_Pulley 2 | E34: =VLOOKUP(G34,'Z0000002-508684 BOM triển k hai'!$G$3:$R$42,12,0) -> Rulo | G34: 34.0 X 31.0 X 34.0 | H34: =VLOOKUP(G34,'Z0000002-508684 BOM triển k hai'!$G$3:$H$42,2,0) -> TT | I34: =$I$1*C34 -> 4 | J34: =$J$1*C34 -> 24
B35: AE33 | C35: 2 | D35: SB6000ZZ | E35: =VLOOKUP(G35,'Z0000002-508684 BOM triển k hai'!$G$3:$R$42,12,0) -> Vòng bi SB6000ZZ --> đổi sang C-SE6000ZZ | G35: 26.0 X 8.0 X 26.0 | H35: =VLOOKUP(G35,'Z0000002-508684 BOM triển k hai'!$G$3:$H$42,2,0) -> VB C-SE6000ZZ | I35: =$I$1*C35 -> 4 | J35: =$J$1*C35 -> 24
B36: AE34 | C36: 2 | D36: STWN10 | E36: =VLOOKUP(G36,'Z0000002-508684 BOM triển k hai'!$G$3:$R$42,12,0) -> phanh trục STWN10 | G36: 1.0 X 15.0 X 13.0 | H36: =VLOOKUP(G36,'Z0000002-508684 BOM triển k hai'!$G$3:$H$42,2,0) -> Phanh trục | I36: =$I$1*C36 -> 4 | J36: =$J$1*C36 -> 24
B37: AE35 | C37: 1 | D37: HTPA18S5M100-B-N10-FC30.0_Misumi | E37: =VLOOKUP(G37,'Z0000002-508684 BOM triển k hai'!$G$3:$R$42,12,0) -> HTPA18S5M100-B-N10-FC30.0 đổi sang HTPA18S5M150-B-N10-FC30.0 | G37: 28.0 X 30.0 X 30.0 | H37: =VLOOKUP(G37,'Z0000002-508684 BOM triển k hai'!$G$3:$H$42,2,0) -> UP | I37: =$I$1*C37 -> 2 | J37: =$J$1*C37 -> 12
... B39: AE37 | C39: 2 | D39: CV3_Shaft 3 | E39: =VLOOKUP(G39,'Z0000002-508684 BOM triển k hai'!$G$3:$R$42,12,0) -> SUS304, điện hóa | G39: 12.0 X 34.0 X 12.0 | H39: =VLOOKUP(G39,'Z0000002-508684 BOM triển k hai'!$G$3:$H$42,2,0) -> TT | I39: =$I$1*C39 -> 4 | J39: =$J$1*C39 -> 24
B40: AE38 | C40: 2 | D40: CV3_AL 7 | E40: =VLOOKUP(G40,'Z0000002-508684 BOM triển k hai'!$G$3:$R$42,12,0) -> AL6061 anode đen | G40: 15.0 X 8.0 X 35.0 | H40: =VLOOKUP(G40,'Z0000002-508684 BOM triển k hai'!$G$3:$H$42,2,0) -> GTAM | I40: =$I$1*C40 -> 4 | J40: =$J$1*C40 -> 24 | K40: đã xong
B41: AE39 | C41: 2 | D41: CV3_AL 8 | E41: =VLOOKUP(G41,'Z0000002-508684 BOM triển k hai'!$G$3:$R$42,12,0) -> AL6061 anode đen | G41: 22.0 X 8.0 X 35.0 | H41: =VLOOKUP(G41,'Z0000002-508684 BOM triển k hai'!$G$3:$H$42,2,0) -> GTAM | I41: =$I$1*C41 -> 4 | J41: =$J$1*C41 -> 24 | K41: đã xong
...

Sheet Z0000002-508704 BOM triển khai
A1: CONVEYOR_Z0000002-508704_ Code Conveyor No 1_AVI Back side - BOM | H1: SL | I1: 2 | J1: ='[1]ducpt trien khai'!$I$31 -> 12
A2: Image | B2: ID Number | C2: Quantity | D2: Standard Number | E2: Sub Category | F2: Category | G2: Visible Part Size | H2: NCC/vật tư | I2: SL | K2: Note 1 | R2: giống cột E
B3: AG01 | C3: 2 | D3: Sensor bracket_SUS304_1 | E3: SUS304, điện hóa | G3: 25.0 X 50.0 X 58.0 | H3: CG | I3: =C3*$I$1 -> 4 | J3: =$J$1*C3 -> 24 | R3: =E3 -> SUS304, điện hóa
B4: AG02 | C4: 1 | D4: ISO 4762 - M5 x 35 | E4: Bulong/ đệm | G4: 40.0 X 9.0 X 9.0 | H4: Bulong/đệm | I4: =C4*$I$1 -> 2 | J4: =$J$1*C4 -> 12 | R4: =E4 -> Bulong/ đệm
B5: AG03 | C5: 1 | D5: CV3_AL 10. | E5: =VLOOKUP(G5,'Z0000002-508684 BOM triển k hai'!$G$3:$R$42,12,0) -> AL6061 anode đen | G5: 15.0 X 8.0 X 35.0 | H5: =VLOOKUP(G5,'Z0000002-508684 BOM triển k hai'!$G$3:$H$42,2,0) -> GTAM | I5: =C5*$I$1 -> 2 | J5: =$J$1*C5 -> 12 | K5: đã xong | R5: =E5 -> AL6061 anode đen
B6: AG04 | C6: 1 | D6: TTBU225T5-100_info-1-18-18_copy | E6: TTBU225T5-100 --> đổi sang C-TTBN225T5-150 | G6: 98.0 X 30.0 X 10.0 | H6: MI | I6: =C6*$I$1 -> 2 | J6: =$J$1*C6 -> 12 | R6: =E6 -> TTBU225T5-100 --> đổi sang C-TTBN225T5-150
B7: AG05 | C7: 1 | D7: CV3_AL 9 | E7: =VLOOKUP(G7,'Z0000002-508684 BOM triển k hai'!$G$3:$R$42,12,0) -> AL6061 anode đen | G7: 60.0 X 20.0 X 63.0 | H7: =VLOOKUP(G7,'Z0000002-508684 BOM triển k hai'!$G$3:$H$42,2,0) -> GTAM | I7: =C7*$I$1 -> 2 | J7: =$J$1*C7 -> 12 | K7: đã xong | R7: =E7 -> AL6061 anode đen
B8: AG06 | C8: 1 | D8: HTPA18S5M100-B-N10_Misumi | E8: =VLOOKUP(G8,'Z0000002-508684 BOM triển k hai'!$G$3:$R$42,12,0) -> HTPA18S5M100-B-N10-FC30.0 đổi sang HTPA18S5M150-B-N10-FC30.0 | G8: 28.0 X 30.0 X 30.0 | H8: =VLOOKUP(G8,'Z0000002-508684 BOM triển k hai'!$G$3:$H$42,2,0) -> UP | I8: =C8*$I$1 -> 2 | J8: =$J$1*C8 -> 12 | R8: =E8 -> HTPA18S5M100-B-N10-FC30.0 đổi sang HTPA18S5M150-B-N10-FC30.0
B9: AG07 | C9: 16 | D9: SB688ZZ | E9: =VLOOKUP(G9,'Z0000002-508684 BOM triển k hai'!$G$3:$R$42,12,0) -> Vòng bi SB688ZZ --> đổi sang C-SE688ZZ | G9: 16.0 X 5.0 X 16.0 | H9: =VLOOKUP(G9,'Z0000002-508684 BOM triển k hai'!$G$3:$H$42,2,0) -> VB C-SE688ZZ | I9: =C9*$I$1 -> 32 | J9: =$J$1*C9 -> 192 | R9: =E9 -> Vòng bi SB688ZZ --> đổi sang C-SE688ZZ
B10: AG08 | C10: 2 | D10: CV3_Shaft 5 | E10: =VLOOKUP(G10,'Z0000002-508684 BOM triển k hai'!$G$3:$R$42,12,0) -> SUS304, điện hóa | G10: 12.0 X 30.0 X 12.0 | H10: =VLOOKUP(G10,'Z0000002-508684 BOM triển k hai'!$G$3:$H$42,2,0) -> TT | I10: =C10*$I$1 -> 4 | J10: =$J$1*C10 -> 24 | R10: =E10 -> SUS304, điện hóa
B11: AG09 | C11: 8 | D11: STWN8_Misumi | E11: =VLOOKUP(G11,'Z0000002-508684 BOM triển k hai'!$G$3:$R$42,12,0) -> Phanh trục STWN8 | G11: 1.0 X 10.0 X 13.0 | H11: =VLOOKUP(G11,'Z0000002-508684 BOM triển k hai'!$G$3:$H$42,2,0) -> Phanh trục | I11: =C11*$I$1 -> 16 | J11: =$J$1*C11 -> 96 | R11: =E11 -> Phanh trục STWN8
B12: AG10 | C12: 4 | D12: CV3_Pulley 1 | E12: =VLOOKUP(G12,'Z0000002-508684 BOM triển k hai'!$G$3:$R$42,12,0) -> Rulo | G12: 24.0 X 23.0 X 24.0 | H12: =VLOOKUP(G12,'Z0000002-508684 BOM triển k hai'!$G$3:$H$42,2,0) -> TT | I12: =C12*$I$1 -> 8 | J12: =$J$1*C12 -> 48 | R12: =E12 -> Rulo
B13: AG11 | C13: 2 | D13: ISO 4017 - M5 x 40 | E13: =E4 -> Bulong/ đệm | G13: 44.0 X 10.0 X 9.0 | H13: =H4 -> Bulong/đệm | I13: =C13*$I$1 -> 4 | J13: =$J$1*C13 -> 24 | R13: =E13 -> Bulong/ đệm
B14: AG12 | C14: 2 | D14: CV3_AL 8 | E14: =VLOOKUP(G14,'Z0000002-508684 BOM triển k hai'!$G$3:$R$42,12,0) -> AL6061 anode đen | G14: 22.0 X 8.0 X 35.0 | H14: =VLOOKUP(G14,'Z0000002-508684 BOM triển k hai'!$G$3:$H$42,2,0) -> GTAM | I14: =C14*$I$1 -> 4 | J14: =$J$1*C14 -> 24 | K14: đã xong | R14: =E14 -> AL6061 anode đen
B15: AG13 | C15: 2 | D15: CV3_AL 7 | E15: =VLOOKUP(G15,'Z0000002-508684 BOM triển k hai'!$G$3:$R$42,12,0) -> AL6061 anode đen | G15: 15.0 X 8.0 X 35.0 | H15: =VLOOKUP(G15,'Z0000002-508684 BOM triển k hai'!$G$3:$H$42,2,0) -> GTAM | I15: =C15*$I$1 -> 4 | J15: =$J$1*C15 -> 24 | K15: đã xong | R15: =E15 -> AL6061 anode đen
B16: AG14 | C16: 2 | D16: CV3_Shaft 3 | E16: =VLOOKUP(G16,'Z0000002-508684 BOM triển k hai'!$G$3:$R$42,12,0) -> SUS304, điện hóa | G16: 12.0 X 34.0 X 12.0 | H16: =VLOOKUP(G16,'Z0000002-508684 BOM triển k hai'!$G$3:$H$42,2,0) -> TT | I16: =C16*$I$1 -> 4 | J16: =$J$1*C16 -> 24 | R16: =E16 -> SUS304, điện hóa
B17: AG15 | C17: 2 | D17: Solid187_1 | E17: Bulong/ đệm | G17: 5.0 X 10.0 X 9.0 | H17: =H4 -> Bulong/đệm | I17: =C17*$I$1 -> 4 | J17: =$J$1*C17 -> 24 | R17: =E17 -> Bulong/ đệm
B18: AG16 | C18: 4 | D18: CV3_Shaft 1 | E18: =VLOOKUP(G18,'Z0000002-508684 BOM triển k hai'!$G$3:$R$42,12,0) -> SUS304, điện hóa | G18: 12.0 X 29.0 X 12.0 | H18: =VLOOKUP(G18,'Z0000002-508684 BOM triển k hai'!$G$3:$H$42,2,0) -> TT | I18: =C18*$I$1 -> 8 | J18: =$J$1*C18 -> 48 | R18: =E18 -> SUS304, điện hóa
B19: AG17 | C19: 4 | D19: CV3_Pulley | E19: =VLOOKUP(G19,'Z0000002-508684 BOM triển k hai'!$G$3:$R$42,12,0) -> Rulo | G19: 21.0 X 20.0 X 21.0 | H19: =VLOOKUP(G19,'Z0000002-508684 BOM triển k hai'!$G$3:$H$42,2,0) -> TT | I19: =C19*$I$1 -> 8 | J19: =$J$1*C19 -> 48 | R19: =E19 -> Rulo
B20: AG18 | C20: 1 | D20: CV3_AL 2_MIR | E20: =E15 -> AL6061 anode đen | G20: 275.0 X 12.0 X 89.0 | H20: =H14 -> GTAM | I20: =C20*$I$1 -> 2 | J20: =$J$1*C20 -> 12 | K20: đã xong | R20: =E20 -> AL6061 anode đen
B21: AG19 | C21: 2 | D21: STWN10 | E21: =VLOOKUP(G21,'Z0000002-508684 BOM triển k hai'!$G$3:$R$42,12,0) -> phanh trục STWN10 | G21: 1.0 X 15.0 X 13.0 | H21: =VLOOKUP(G21,'Z0000002-508684 BOM triển k hai'!$G$3:$H$42,2,0) -> Phanh trục | I21: =C21*$I$1 -> 4 | J21: =$J$1*C21 -> 24 | R21: =E21 -> phanh trục STWN10
B22: AG20 | C22: 2 | D22: SB6000ZZ | E22: =VLOOKUP(G22,'Z0000002-508684 BOM triển k hai'!$G$3:$R$42,12,0) -> Vòng bi SB6000ZZ --> đổi sang C-SE6000ZZ | G22: 26.0 X 8.0 X 26.0 | H22: =VLOOKUP(G22,'Z0000002-508684 BOM triển k hai'!$G$3:$H$42,2,0) -> VB C-SE6000ZZ | I22: =C22*$I$1 -> 4 | J22: =$J$1*C22 -> 24 | R22: =E22 -> Vòng bi SB6000ZZ --> đổi sang C-SE6000ZZ
B23: AG21 | C23: 2 | D23: CV3_Pb108-2 | E23: PB108 | G23: 276.0 X 19.0 X 11.0 | H23: =H20 -> GTAM | I23: =C23*$I$1 -> 4 | J23: =$J$1*C23 -> 24 | K23: chưa gc | R23: =E23 -> PB108
B24: AG22 | C24: 2 | D24: CV3_Belt 1 | E24: belt PU đen, chống tĩnh điện, độ dày 1.5m, bản rộng 20mm, chu vi 650mm (đo mép trong 655mm, chốt căn chỉnh ở giữa) | G24: 274.0 X 20.0 X 80.0 | H24: Belt | I24: =C24*$I$1 -> 4 | J24: =$J$1*C24 -> 24 | R24: =E24 -> belt PU đen, chống tĩnh điện, độ dày 1.5m, bản rộng 20mm, chu vi 650mm (đo mép trong 655mm, chốt căn chỉnh ở giữa)
B25: AG23 | C25: 2 | D25: CV3_Pb108-1 | E25: =E23 -> PB108 | G25: 224.0 X 26.0 X 16.0 | H25: =H23 -> GTAM | I25: =C25*$I$1 -> 4 | J25: =$J$1*C25 -> 24 | K25: chưa gc | R25: =E25 -> PB108
B26: AG24 | C26: 1 | D26: HTPA18S5M100-A-N8 | E26: =VLOOKUP(G26,'Z0000002-508684 BOM triển k hai'!$G$3:$R$42,12,0) -> HTPA18S5M100-A-N8-FC30.0 đổi sang HTPA18S5M150-A-N8-FC30.0 | G26: 31.0 X 16.0 X 31.0 | H26: =VLOOKUP(G26,'Z0000002-508684 BOM triển k hai'!$G$3:$H$42,2,0) -> UP | I26: =C26*$I$1 -> 2 | J26: =$J$1*C26 -> 12 | R26: =E26 -> HTPA18S5M100-A-N8-FC30.0 đổi sang HTPA18S5M150-A-N8-FC30.0
B27: AG25 | C27: 2 | D27: CV3_Pulley 2 | E27: =VLOOKUP(G27,'Z0000002-508684 BOM triển k hai'!$G$3:$R$42,12,0) -> Rulo | G27: 34.0 X 31.0 X 34.0 | H27: =VLOOKUP(G27,'Z0000002-508684 BOM triển k hai'!$G$3:$H$42,2,0) -> TT | I27: =C27*$I$1 -> 4 | J27: =$J$1*C27 -> 24 | R27: =E27 -> Rulo
B28: AG26 | C28: 1 | D28: CV3_AL 2 | E28: =E20 -> AL6061 anode đen | G28: 275.0 X 12.0 X 89.0 | H28: =H23 -> GTAM | I28: =C28*$I$1 -> 2 | J28: =$J$1*C28 -> 12 | K28: đã xong | R28: =E28 -> AL6061 anode đen
B29: AG27 | C29: 1 | D29: CV3_Shaft 4 | E29: =VLOOKUP(G29,'Z0000002-508684 BOM triển k hai'!$G$3:$R$42,12,0) -> Trục | G29: 11.0 X 10.0 X 205.0 | H29: =VLOOKUP(G29,'Z0000002-508684 BOM triển k hai'!$G$3:$H$42,2,0) -> TT | I29: =C29*$I$1 -> 2 | J29: =$J$1*C29 -> 12 | R29: =E29 -> Trục
B30: AG28 | C30: 1 | D30: CV3_AL 3 | E30: =E28 -> AL6061 anode đen | G30: 275.0 X 200.0 X 12.0 | H30: =H28 -> GTAM | I30: =C30*$I$1 -> 2 | J30: =$J$1*C30 -> 12 | K30: đã xong | R30: =E30 -> AL6061 anode đen
B31: AG29 | C31: 1 | D31: S6I06G-GX | E31: =VLOOKUP(G31,'Z0000002-508684 BOM triển k hai'!$G$3:$R$42,12,0) -> S6I06GX-12CE và bộ đk tốc độ SUA06IX-V12 | G31: 100.0 X 60.0 X 62.0 | H31: =VLOOKUP(G31,'Z0000002-508684 BOM triển k hai'!$G$3:$H$42,2,0) -> SPG | I31: =C31*$I$1 -> 2 | J31: =$J$1*C31 -> 12 | K31: ='Z0000002-508703 BOM triển khai'!K24 -> NG báo đã nhận 27 set, đủ lô 7CV | R31: =E31 -> S6I06GX-12CE và bộ đk tốc độ SUA06IX-V12
B32: AG30 | C32: 1 | D32: S6KA3-15 | E32: =VLOOKUP(G32,'Z0000002-508684 BOM triển k hai'!$G$3:$R$42,12,0) -> hộp số S6KA15B | G32: 60.0 X 60.0 X 63.0 | H32: =VLOOKUP(G32,'Z0000002-508684 BOM triển k hai'!$G$3:$H$42,2,0) -> SPG | I32: =C32*$I$1 -> 2 | J32: =$J$1*C32 -> 12 | K32: =K31 -> NG báo đã nhận 27 set, đủ lô 7CV | R32: =E32 -> hộp số S6KA15B
H34: ='Z0000002-508703 BOM triển khai'!H43 -> Belt | I34: ='Z0000002-508703 BOM triển khai'!I43 -> đã nhận đủ hàng 9/4 | J34: ='Z0000002-508703 BOM triển khai'!J43 -> đã đặt hàng 10/4, hẹn 25/4 giao 50%, 5/5 giao nốt | K34: ='Z0000002-508703 BOM triển khai'!K43 -> 0
H35: ='Z0000002-508703 BOM triển khai'!H44 -> CG | I35: ='Z0000002-508703 BOM triển khai'!I44 -> đã xong 9/4 | J35: ='Z0000002-508703 BOM triển khai'!J44 -> 0 | K35: ='Z0000002-508703 BOM triển khai'!K44 -> 0
H36: ='Z0000002-508703 BOM triển khai'!H45 -> Chốt cài | I36: ='Z0000002-508703 BOM triển khai'!I45 -> đã tồn kho | J36: ='Z0000002-508703 BOM triển khai'!J45 -> đã tồn kho | K36: ='Z0000002-508703 BOM triển khai'!K45 -> 0
H37: ='Z0000002-508703 BOM triển khai'!H46 -> GTAM | I37: ='Z0000002-508703 BOM triển khai'!I46 -> 9/4 đã xong | J37: ='Z0000002-508703 BOM triển khai'!J46 -> 0 | K37: ='Z0000002-508703 BOM triển khai'!K46 -> 0
H38: ='Z0000002-508703 BOM triển khai'!H47 -> MI | I38: ='Z0000002-508703 BOM triển khai'!I47 -> đã chốt đặt, dự kiến về trước 10/4 | J38: ='Z0000002-508703 BOM triển khai'!J47 -> đã nhận đủ 13/4, | K38: ='Z0000002-508703 BOM triển khai'!K47 -> 0
H39: ='Z0000002-508703 BOM triển khai'!H48 -> TT | I39: ='Z0000002-508703 BOM triển khai'!I48 -> đã giao lô đầu 30 set | J39: ='Z0000002-508703 BOM triển khai'!J48 -> 9/4 nhận 159 bộ, thiếu rulo chủ động giao sau | K39: ='Z0000002-508703 BOM triển khai'!K48 -> 0
H40: ='Z0000002-508703 BOM triển khai'!H49 -> Phanh trục | I40: ='Z0000002-508703 BOM triển khai'!I49 -> đã tồn kho sẵn | J40: ='Z0000002-508703 BOM triển khai'!J49 -> đã tồn kho sẵn | K40: ='Z0000002-508703 BOM triển khai'!K49 -> 0
H41: ='Z0000002-508703 BOM triển khai'!H50 -> SPG | I41: ='Z0000002-508703 BOM triển khai'!I50 -> NG báo đã nhận 27 set, đủ lô 7CV | J41: ='Z0000002-508703 BOM triển khai'!J50 -> 0 | K41: ='Z0000002-508703 BOM triển khai'!K50 -> 0
...

Sheet Z0000002-508707 BOM triển khai
A1: 3D_Z0000002-508707 - BOM | H1: SL | I1: 9 | J1: ='[1]ducpt trien khai'!$I$32 -> 54
A2: Image | B2: ID Number | C2: Quantity | D2: Standard Number | E2: Sub Category | F2: Category | G2: Visible Part Size | H2: NCC/vật tư | I2: SL | K2: Note 1
B3: AH01 | C3: 1 | D3: TTBU250T5-100_info-1-18-18_L=570mm | E3: TTBU250T5-100 --> đổi sang C-TTBN250T5-150 | G3: 110.0 X 30.0 X 10.0 | H3: MI | I3: =$I$1*C3 -> 9 | J3: =$J$1*C3 -> 54
B4: AH02 | C4: 8 | D4: STWN8_L=570mm | E4: =VLOOKUP(G4,'Z0000002-508704 BOM triển khai'!$G$3:$R$32,12,0) -> Phanh trục STWN8 | G4: 1.0 X 10.0 X 13.0 | H4: =VLOOKUP(G4,'Z0000002-508704 BOM triển khai'!$G$3:$H$32,2,0) -> Phanh trục | I4: =$I$1*C4 -> 72 | J4: =$J$1*C4 -> 432
B5: AH03 | C5: 2 | D5: STWN10_L=570mm | E5: =VLOOKUP(G5,'Z0000002-508704 BOM triển khai'!$G$3:$R$32,12,0) -> phanh trục STWN10 | G5: 1.0 X 15.0 X 13.0 | H5: =VLOOKUP(G5,'Z0000002-508704 BOM triển khai'!$G$3:$H$32,2,0) -> Phanh trục | I5: =$I$1*C5 -> 18 | J5: =$J$1*C5 -> 108
B6: AH04 | C6: 16 | D6: SB688ZZ_L=570mm | E6: =VLOOKUP(G6,'Z0000002-508704 BOM triển khai'!$G$3:$R$32,12,0) -> Vòng bi SB688ZZ --> đổi sang C-SE688ZZ | G6: 16.0 X 5.0 X 16.0 | H6: =VLOOKUP(G6,'Z0000002-508704 BOM triển khai'!$G$3:$H$32,2,0) -> VB C-SE688ZZ | I6: =$I$1*C6 -> 144 | J6: =$J$1*C6 -> 864
B7: AH05 | C7: 2 | D7: SB6000ZZ_L=570mm | E7: =VLOOKUP(G7,'Z0000002-508704 BOM triển khai'!$G$3:$R$32,12,0) -> Vòng bi SB6000ZZ --> đổi sang C-SE6000ZZ | G7: 26.0 X 8.0 X 26.0 | H7: =VLOOKUP(G7,'Z0000002-508704 BOM triển khai'!$G$3:$H$32,2,0) -> VB C-SE6000ZZ | I7: =$I$1*C7 -> 18 | J7: =$J$1*C7 -> 108
B8: AH06 | C8: 1 | D8: HTPA18S5M100-B-N10-FC30.0_L=570mm | E8: =VLOOKUP(G8,'Z0000002-508704 BOM triển khai'!$G$3:$R$32,12,0) -> HTPA18S5M100-B-N10-FC30.0 đổi sang HTPA18S5M150-B-N10-FC30.0 | G8: 28.0 X 30.0 X 30.0 | H8: =VLOOKUP(G8,'Z0000002-508704 BOM triển khai'!$G$3:$H$32,2,0) -> UP | I8: =$I$1*C8 -> 9 | J8: =$J$1*C8 -> 54
B9: AH07 | C9: 1 | D9: HTPA18S5M100-A-N8-FC30.0_L=570mm | E9: =VLOOKUP(G9,'Z0000002-508704 BOM triển khai'!$G$3:$R$32,12,0) -> HTPA18S5M100-A-N8-FC30.0 đổi sang HTPA18S5M150-A-N8-FC30.0 | G9: 31.0 X 16.0 X 31.0 | H9: =VLOOKUP(G9,'Z0000002-508704 BOM triển khai'!$G$3:$H$32,2,0) -> UP | I9: =$I$1*C9 -> 9 | J9: =$J$1*C9 -> 54
B10: AH08 | C10: 2 | D10: Auto Vision Inspection TOP - P220_L=570mm | E10: =E11 -> AL6061 anode đen | G10: 20.0 X 8.0 X 35.0 | H10: =H11 -> GTAM | I10: =$I$1*C10 -> 18 | J10: =$J$1*C10 -> 108 | K10: đã xong
B11: AH09 | C11: 2 | D11: Auto Vision Inspection TOP - P219_L=570mm | E11: =VLOOKUP(G11,'Z0000002-508704 BOM triển khai'!$G$3:$R$32,12,0) -> AL6061 anode đen | G11: 15.0 X 8.0 X 35.0 | H11: =VLOOKUP(G11,'Z0000002-508704 BOM triển khai'!$G$3:$H$32,2,0) -> GTAM | I11: =$I$1*C11 -> 18 | J11: =$J$1*C11 -> 108 | K11: đã xong
B12: AH10 | C12: 4 | D12: Auto Vision Inspection TOP - P218_L=570mm | E12: =VLOOKUP(G12,'Z0000002-508704 BOM triển khai'!$G$3:$R$32,12,0) -> SUS304, điện hóa | G12: 12.0 X 29.0 X 12.0 | H12: =VLOOKUP(G12,'Z0000002-508704 BOM triển khai'!$G$3:$H$32,2,0) -> TT | I12: =$I$1*C12 -> 36 | J12: =$J$1*C12 -> 216
B13: AH11 | C13: 4 | D13: Auto Vision Inspection TOP - P217_L=570mm | E13: =VLOOKUP(G13,'Z0000002-508704 BOM triển khai'!$G$3:$R$32,12,0) -> Rulo | G13: 21.0 X 20.0 X 21.0 | H13: =VLOOKUP(G13,'Z0000002-508704 BOM triển khai'!$G$3:$H$32,2,0) -> TT | I13: =$I$1*C13 -> 36 | J13: =$J$1*C13 -> 216
B14: AH12 | C14: 1 | D14: Auto Vision Inspection TOP - P215_L=570mm | E14: =VLOOKUP(G14,'Z0000002-508704 BOM triển khai'!$G$3:$R$32,12,0) -> Rulo | G14: 34.0 X 31.0 X 34.0 | H14: =VLOOKUP(G14,'Z0000002-508704 BOM triển khai'!$G$3:$H$32,2,0) -> TT | I14: =$I$1*C14 -> 9 | J14: =$J$1*C14 -> 54
B15: AH13 | C15: 2 | D15: Auto Vision Inspection TOP - P213_L=570mm | E15: =VLOOKUP(G15,'Z0000002-508704 BOM triển khai'!$G$3:$R$32,12,0) -> SUS304, điện hóa | G15: 12.0 X 30.0 X 12.0 | H15: =VLOOKUP(G15,'Z0000002-508704 BOM triển khai'!$G$3:$H$32,2,0) -> TT | I15: =$I$1*C15 -> 18 | J15: =$J$1*C15 -> 108
B16: AH14 | C16: 2 | D16: Auto Vision Inspection TOP - P211_L=570mm | E16: =VLOOKUP(G16,'Z0000002-508704 BOM triển khai'!$G$3:$R$32,12,0) -> SUS304, điện hóa | G16: 12.0 X 34.0 X 12.0 | H16: =VLOOKUP(G16,'Z0000002-508704 BOM triển khai'!$G$3:$H$32,2,0) -> TT | I16: =$I$1*C16 -> 18 | J16: =$J$1*C16 -> 108
B17: AH15 | C17: 4 | D17: Auto Vision Inspection TOP - P210_L=570mm | E17: =VLOOKUP(G17,'Z0000002-508704 BOM triển khai'!$G$3:$R$32,12,0) -> Rulo | G17: 24.0 X 23.0 X 24.0 | H17: =VLOOKUP(G17,'Z0000002-508704 BOM triển khai'!$G$3:$H$32,2,0) -> TT | I17: =$I$1*C17 -> 36 | J17: =$J$1*C17 -> 216
B18: AH16 | C18: 1 | D18: Auto Vision Inspection TOP - P209_L=570mm | E18: =VLOOKUP(G18,'Z0000002-508704 BOM triển khai'!$G$3:$R$32,12,0) -> Rulo | G18: 34.0 X 31.0 X 34.0 | H18: =VLOOKUP(G18,'Z0000002-508704 BOM triển khai'!$G$3:$H$32,2,0) -> TT | I18: =$I$1*C18 -> 9 | J18: =$J$1*C18 -> 54
B19: AH17 | C19: 1 | D19: Auto Vision Inspection TOP - P208_L=570mm | E19: =VLOOKUP(G19,'Z0000002-508704 BOM triển khai'!$G$3:$R$32,12,0) -> Trục | G19: 11.0 X 10.0 X 205.0 | H19: =VLOOKUP(G19,'Z0000002-508704 BOM triển khai'!$G$3:$H$32,2,0) -> TT | I19: =$I$1*C19 -> 9 | J19: =$J$1*C19 -> 54
B20: AH18 | C20: 1 | D20: Auto CTQ Machine - P076_L=570mm | E20: =E11 -> AL6061 anode đen | G20: 557.0 X 200.0 X 12.0 | H20: =H11 -> GTAM | I20: =$I$1*C20 -> 9 | J20: =$J$1*C20 -> 54 | K20: đã xong
B21: AH19 | C21: 1 | D21: Auto CTQ Machine - P075_L=570mm | E21: =E20 -> AL6061 anode đen | G21: 557.0 X 12.0 X 89.0 | H21: =H20 -> GTAM | I21: =$I$1*C21 -> 9 | J21: =$J$1*C21 -> 54 | K21: đã xong
B22: AH20 | C22: 1 | D22: Auto CTQ Machine - P074_L=570mm | E22: =E21 -> AL6061 anode đen | G22: 557.0 X 12.0 X 89.0 | H22: =H21 -> GTAM | I22: =$I$1*C22 -> 9 | J22: =$J$1*C22 -> 54 | K22: đã xong
B23: AH21 | C23: 2 | D23: Auto CTQ Machine - P073_L=570mm | E23: PB108 | G23: 506.0 X 26.0 X 16.0 | H23: =H22 -> GTAM | I23: =$I$1*C23 -> 18 | J23: =$J$1*C23 -> 108 | K23: chưa gc
B24: AH22 | C24: 1 | D24: Auto CTQ Machine - P072_L=570mm | E24: =E23 -> PB108 | G24: 557.0 X 15.0 X 10.0 | H24: =H23 -> GTAM | I24: =$I$1*C24 -> 9 | J24: =$J$1*C24 -> 54 | K24: đã xong
B25: AH23 | C25: 2 | D25: Auto CTQ Machine - D_X_E2y Belt CV 405mm_L=570mm | E25: belt PU đen, chống tĩnh điện, ép viền chống xước, dày 1.5mm, bản rộng 20mm, chu vi 1210mm ( đo mép trong 1219mm, chốt căn chỉnh ở giữa ) | G25: 556.0 X 20.0 X 80.0 | H25: Belt | I25: =$I$1*C25 -> 18 | J25: =$J$1*C25 -> 108
B26: AH24 | C26: 1 | D26: 260226_Order_PB108_0822 | E26: =E24 -> PB108 | G26: 557.0 X 15.0 X 10.0 | H26: GTAM | I26: =$I$1*C26 -> 9 | J26: =$J$1*C26 -> 54 | K26: đã xong
B27: AH25 | C27: 1 | D27: 260226_Order_AL6061_0828 | E27: =E22 -> AL6061 anode đen | G27: 10.0 X 101.0 X 20.0 | H27: =H24 -> GTAM | I27: =$I$1*C27 -> 9 | J27: =$J$1*C27 -> 54 | K27: đã xong
B28: AH26 | C28: 4 | D28: 210226_Order_SUS304_1322 | E28: SUS304, điện hóa | G28: 52.0 X 75.0 X 30.0 | H28: CG | I28: =$I$1*C28 -> 36 | J28: =$J$1*C28 -> 216
B29: AH27 | C29: 1 | D29: 210226_Order_Al6061_0930 | E29: =E22 -> AL6061 anode đen | G29: 10.0 X 63.0 X 90.0 | H29: =H27 -> GTAM | I29: =$I$1*C29 -> 9 | J29: =$J$1*C29 -> 54 | K29: đã xong
B30: AH28 | C30: 2 | D30: 210226_Order_AL6061_0929 | E30: =E29 -> AL6061 anode đen | G30: 10.0 X 30.0 X 35.0 | H30: =H29 -> GTAM | I30: =$I$1*C30 -> 18 | J30: =$J$1*C30 -> 108 | K30: đã xong
B31: AH29 | C31: 2 | D31: 151225_Oder_SUS304_1412 | E31: =E28 -> SUS304, điện hóa | G31: 11.0 X 24.0 X 23.0 | H31: =H28 -> CG | I31: =$I$1*C31 -> 18 | J31: =$J$1*C31 -> 108
