Workbook
Name Material_list: OFFSET(Table14[[#Headers],[Tên vật liệu tiếng Anh]],1,0,COUNTA(Table14[Tên vật liệu tiếng Anh]),1)
Name Material_list: OFFSET(#REF!,1,0,COUNTA(#REF!),1)
Name Process_list: OFFSET(Table25[[#Headers],[Tên công đoạn tiếng Anh]],1,0,COUNTA(Table25[Tên công đoạn tiếng Anh]),1)
Name Process_list: OFFSET(#REF!,1,0,COUNTA(#REF!),1)

Sheet Z0000002-502653 BOM triển khai
A1: Z0000002-502653_BANG TAI DIPPING R01 | K1: Số lượng | L1: 2
A2: Image | B2: ID Number | C2: Quantity | D2: Standard Number | E2: Sub Category | I2: Category | J2: Visible Part Size | K2: NCC/Vật tư | L2: Số lượng | M2: Note 1 | N2: Note 2 | O2: Note 3
B3: R01 | C3: 6 | D3: KES6-20 | I3: 8000 | J3: 20.0 X 6.0 X 6.0 | K3: Chốt cài | L3: =$L$1*C3 -> 12 | M3: đã tồn kho sẵn
B4: R02 | C4: 12 | D4: STWN20 | I4: 10000 | J4: 2.0 X 26.0 X 24.0 | K4: Phanh trục | L4: =$L$1*C4 -> 24 | M4: =M3 -> đã tồn kho sẵn
B5: R03 | C5: 1 | D5: C1609-24-P-00154 | E5: SUS304 | G5: PG | H5: 1400 | I5: 450000 | J5: 601.0 X 21.0 X 20.0 | K5: TT | L5: =$L$1*C5 -> 2 | M5: đã yc gửi data/ có thể lv với NCC mới
B6: R04 | C6: 1 | D6: C1609-24-P-00395 | E6: SUS304 | G6: PG | H6: 1400 | I6: =I5 -> 450000 | J6: 570.0 X 21.0 X 20.0 | K6: =K5 -> TT | L6: =$L$1*C6 -> 2 | M6: =M5 -> đã yc gửi data/ có thể lv với NCC mới
B7: R05 | C7: 3 | D7: C1609-24-P-00393 | E7: SUS304 | G7: MAH | H7: 585 | I7: 145000 | J7: 750.0 X 5.0 X 20.0 | K7: Vitech | L7: =$L$1*C7 -> 6 | M7: =M6 -> đã yc gửi data/ có thể lv với NCC mới
B8: R06 | C8: 3 | D8: C1609-24-P-00394 | E8: Acetal black | H8: 330 | I8: 140000 | J8: 750.0 X 15.0 X 20.0 | K8: GTAM | L8: =$L$1*C8 -> 6
B9: R07 | C9: 8 | D9: B6203ZZ | E9: Vòng bi B6203ZZ --> đổi sang C-E6203ZZ | I9: 42000 | J9: 12.0 X 40.0 X 40.0 | K9: VB | L9: =$L$1*C9 -> 16 | M9: hàng đã về 27/3
B10: R08 | C10: 4 | D10: C1609-24-P-00381 | E10: SUS304 --> đổi sang AL6061, anode màu xám bạc | H10: 130 | I10: 50000 | J10: 60.0 X 10.0 X 30.0 | K10: GTAM | L10: =$L$1*C10 -> 8 | M10: =M8 -> 0
B11: R09 | C11: 1 | D11: C1609-24-P-00387 | E11: AL6061 màu xám bạc | H11: 398 | I11: 240000 | J11: 30.0 X 152.0 X 60.0 | K11: GTAM | L11: =$L$1*C11 -> 2 | M11: =M10 -> 0
B12: R10 | C12: 2 | D12: C1609-24-P-00380 | E12: =E11 -> AL6061 màu xám bạc | H12: 9 | I12: 20000 | J12: 13.0 X 10.0 X 28.0 | K12: =K11 -> GTAM | L12: =$L$1*C12 -> 4 | M12: =M11 -> 0
B13: R11 | C13: 2 | D13: C1609-24-P-00376 | E13: =E12 -> AL6061 màu xám bạc | H13: 140 | I13: 115000 | J13: 30.0 X 60.0 X 60.0 | K13: =K12 -> GTAM | L13: =$L$1*C13 -> 4 | M13: =M12 -> 0
B14: R12 | C14: 2 | D14: C1609-24-P-00373 | E14: Nhôm định hình 60x30mm, chiều dài 629mm | H14: 1000 | I14: 175000 | J14: 31.0 X 61.0 X 629.0 | K14: AL Profile | L14: =$L$1*C14 -> 4 | M14: 10/4 đã nhận hàng
B15: R13 | C15: 1 | D15: C1609-24-P-00386 | E15: =E13 -> AL6061 màu xám bạc | H15: 400 | I15: =I11 -> 240000 | J15: 30.0 X 152.0 X 60.0 | K15: =K13 -> GTAM | L15: =$L$1*C15 -> 2
B16: R14 | C16: 2 | D16: C1609-24-P-00379 | E16: =E15 -> AL6061 màu xám bạc | I16: =I12 -> 20000 | J16: 13.0 X 10.0 X 28.0 | K16: =K15 -> GTAM | L16: =$L$1*C16 -> 4
B17: R15 | C17: 1 | D17: C1609-24-P-00378 | E17: =E16 -> AL6061 màu xám bạc | H17: 228 | I17: 120000 | J17: 30.0 X 95.0 X 60.0 | K17: =K16 -> GTAM | L17: =$L$1*C17 -> 2
B18: R16 | C18: 1 | D18: C1609-24-P-00377 | E18: =E17 -> AL6061 màu xám bạc | I18: =I17 -> 120000 | J18: 30.0 X 95.0 X 60.0 | K18: =K17 -> GTAM | L18: =$L$1*C18 -> 2
B19: R17 | C19: 3 | D19: HTBN1800S5M-150_info-1-32-32 | E19: HTBN1800S5M-150 , đổi sang C-HTBN1800S5M-150 | I19: 195000 | J19: 873.0 X 53.0 X 15.0 | K19: MI | L19: =$L$1*C19 -> 6 | M19: ducpt đã nhận hàng 27/3
B20: R18 | C20: 2 | D20: C1609-24-P-00436 | E20: =E10 -> SUS304 --> đổi sang AL6061, anode màu xám bạc | H20: 200 | I20: 80000 | J20: 30.0 X 110.0 X 49.0 | K20: =K10 -> GTAM | L20: =$L$1*C20 -> 4
B21: R19 | C21: 1 | D21: C1609-24-P-00125_MIR_MIR | E21: SUS304 | H21: 1980 | I21: 520000 | J21: 386.0 X 40.0 X 327.0 | K21: CG | L21: =$L$1*C21 -> 2 | M21: Nguyện đặt NCC nào đó
B22: R20 | C22: 1 | D22: C1609-24-P-00125_MIR | E22: =E21 -> SUS304 | I22: =I21 -> 520000 | J22: 386.0 X 40.0 X 327.0 | K22: =K21 -> CG | L22: =$L$1*C22 -> 2 | M22: =M21 -> Nguyện đặt NCC nào đó
B23: R21 | C23: 2 | D23: C1609-24-P-00436 copy | E23: =E20 -> SUS304 --> đổi sang AL6061, anode màu xám bạc | H23: 608 | I23: 220000 | J23: 30.0 X 120.0 X 49.0 | K23: =K20 -> GTAM | L23: =$L$1*C23 -> 4
B24: R22 | C24: 1 | D24: C1609-24-P-00128_MIR | E24: Acetal black | H24: 140 | I24: 84000 | J24: 250.0 X 40.0 X 12.0 | K24: GTAM | L24: =$L$1*C24 -> 2
B25: R23 | C25: 1 | D25: C1609-24-P-00128 | E25: Acetal black | H25: =H24 -> 140 | I25: =I24 -> 84000 | J25: 250.0 X 40.0 X 12.0 | K25: =K24 -> GTAM | L25: =$L$1*C25 -> 2
B26: R24 | C26: 6 | D26: HTPA32S5M150-A-N20-FC52.0_b | E26: HTPA32S5M150-A-N20-FC52.0 | G26: UP | H26: 130 | I26: 200000 | J26: 22.0 X 52.0 X 52.0 | K26: UP | L26: =$L$1*C26 -> 12 | M26: dđã nhận đủ
B27: R25 | C27: 12 | D27: SET-SCREW6-5 | I27: 5000 | J27: 5.0 X 6.0 X 6.0 | K27: Vít trí | L27: =$L$1*C27 -> 24 | M27: tồn kho sẵn
B28: R26 | C28: 2 | D28: HTPA20S5M150-A-N12_b | E28: HTPA20S5M150-A-N12 | G28: =G26 -> UP | H28: 95000 | I28: 175000 | J28: 22.0 X 36.0 X 36.0 | K28: =K26 -> UP | L28: =$L$1*C28 -> 4 | M28: =M26 -> dđã nhận đủ
B29: R27 | C29: 4 | D29: SET-SCREW4-3 | I29: =I27 -> 5000 | J29: 3.0 X 4.0 X 4.0 | K29: =K27 -> Vít trí | L29: =$L$1*C29 -> 8 | M29: =M27 -> tồn kho sẵn
B30: R28 | C30: 1 | D30: C1609-24-P-00390 | E30: Mica trong | I30: 65000 | J30: 90.0 X 160.0 X 3.0 | K30: GTAM | L30: =$L$1*C30 -> 2
B31: R29 | C31: 1 | D31: C1609-24-P-00389 | E31: SUS304 | H31: 160 | I31: 65000 | J31: 90.0 X 160.0 X 30.0 | K31: =K22 -> CG | L31: =$L$1*C31 -> 2 | M31: =M22 -> Nguyện đặt NCC nào đó
B32: R30 | C32: 1 | D32: C1609-24-P-00388_MIR2 | E32: SUS304 | H32: 470 | I32: 180000 | J32: 90.0 X 160.0 X 5.0 | K32: Vitech | L32: =$L$1*C32 -> 2 | M32: chưa gửi data
B33: R31 | C33: 1 | D33: HTBN300S5M-150_info-1-20-20 | E33: HTBN300S5M-150, đổi sang C-HTBN300S5M-150 | I33: 110000 | J33: 134.0 X 34.0 X 15.0 | K33: MI | L33: =$L$1*C33 -> 2 | M33: =M19 -> ducpt đã nhận hàng 27/3
B34: R32 | C34: 1 | D34: S9KB18B | I34: 1900000 | J34: 90.0 X 90.0 X 75.0 | K34: SPG | L34: =$L$1*C34 -> 2 | M34: đaã đặt Thế Long, 18/4 giao
B35: R33 | C35: 1 | D35: S9I40GX-V12CE | I35: 2300000 | J35: 135.0 X 90.0 X 92.0 | K35: =K34 -> SPG | L35: =$L$1*C35 -> 2 | M35: =M34 -> đaã đặt Thế Long, 18/4 giao
B36: R34 | C36: 6 | D36: C1609-24-P-00422 | E36: =E23 -> SUS304 --> đổi sang AL6061, anode màu xám bạc | H36: 31 | I36: 80000 | J36: 15.0 X 35.0 X 30.0 | K36: GTAM | L36: =$L$1*C36 -> 12
B37: R35 | C37: 3 | D37: C1609-24-P-00423 copy | E37: SUS304 | H37: 27 | I37: 50000 | J37: 20.0 X 30.0 X 49.0 | K37: CG | L37: =$L$1*C37 -> 6 | M37: =M31 -> Nguyện đặt NCC nào đó
B38: R36 | C38: 6 | D38: C1609-24-P-00420 | E38: SUS304 | H38: 62 | I38: 70000 | J38: 10.0 X 10.0 X 107.0 | K38: =K5 -> TT | L38: =$L$1*C38 -> 12 | M38: chưa có data, sẽ có NCC mới
B39: R37 | C39: 6 | D39: C1609-24-P-00396 | E39: SUS304 | H39: 27 | I39: 50000 | J39: 18.0 X 40.0 X 8.0 | K39: Vitech | L39: =$L$1*C39 -> 12 | M39: =M32 -> chưa gửi data
B40: R38 | C40: 3 | D40: Part93 | E40: SUS304 | H40: 50 | I40: 50000 | J40: 3.0 X 75.0 X 61.0 | K40: CG | L40: =$L$1*C40 -> 6 | M40: =M22 -> Nguyện đặt NCC nào đó
...

Sheet Z0000002-502654 BOM triển kh ai
A1: Z0000002-502654_BANG TAI DIPPING L01 | G1: Số lượng | H1: 2
A2: Image | B2: ID Number | C2: Quantity | D2: Standard Number | F2: Visible Part Size | G2: NCC | I2: Note 1 | J2: Note 2 | K2: Note 3
B3: S01 | C3: 3 | D3: HTBN1800S5M-150_info-1-32-32 | E3: =VLOOKUP(D3,'Z0000002-502653 BOM triển khai'!$D$3:$J$43,2,0) -> HTBN1800S5M-150 , đổi sang C-HTBN1800S5M-150 | F3: 873.0 X 53.0 X 15.0 | G3: =VLOOKUP(D3,'Z0000002-502653 BOM triển khai'!$D$3:$K$43,8,0) -> MI | H3: =C3*$H$1 -> 6 | I3: ='Z0000002-502653 BOM triển khai'!M19 -> ducpt đã nhận hàng 27/3
B4: S02 | C4: 1 | D4: C1609-24-P-00125_MIR_MIR | E4: =VLOOKUP(D4,'Z0000002-502653 BOM triển khai'!$D$3:$J$43,2,0) -> SUS304 | F4: 386.0 X 40.0 X 327.0 | G4: =VLOOKUP(D4,'Z0000002-502653 BOM triển khai'!$D$3:$K$43,8,0) -> CG | H4: =C4*$H$1 -> 2
B5: S03 | C5: 1 | D5: C1609-24-P-00125_MIR | E5: =VLOOKUP(D5,'Z0000002-502653 BOM triển khai'!$D$3:$J$43,2,0) -> SUS304 | F5: 386.0 X 40.0 X 327.0 | G5: =VLOOKUP(D5,'Z0000002-502653 BOM triển khai'!$D$3:$K$43,8,0) -> CG | H5: =C5*$H$1 -> 2
B6: S04 | C6: 2 | D6: C1609-24-P-00436 copy | E6: =VLOOKUP(D6,'Z0000002-502653 BOM triển khai'!$D$3:$J$43,2,0) -> SUS304 --> đổi sang AL6061, anode màu xám bạc | F6: 30.0 X 120.0 X 49.0 | G6: =VLOOKUP(D6,'Z0000002-502653 BOM triển khai'!$D$3:$K$43,8,0) -> GTAM | H6: =C6*$H$1 -> 4
B7: S05 | C7: 1 | D7: C1609-24-P-00128_MIR | E7: =VLOOKUP(D7,'Z0000002-502653 BOM triển khai'!$D$3:$J$43,2,0) -> Acetal black | F7: 250.0 X 40.0 X 12.0 | G7: =VLOOKUP(D7,'Z0000002-502653 BOM triển khai'!$D$3:$K$43,8,0) -> GTAM | H7: =C7*$H$1 -> 2
B8: S06 | C8: 1 | D8: C1609-24-P-00128 | E8: =VLOOKUP(D8,'Z0000002-502653 BOM triển khai'!$D$3:$J$43,2,0) -> Acetal black | F8: 250.0 X 40.0 X 12.0 | G8: =VLOOKUP(D8,'Z0000002-502653 BOM triển khai'!$D$3:$K$43,8,0) -> GTAM | H8: =C8*$H$1 -> 2
B9: S07 | C9: 6 | D9: KES6-20 | E9: =VLOOKUP(D9,'Z0000002-502653 BOM triển khai'!$D$3:$J$43,2,0) | F9: 20.0 X 6.0 X 6.0 | G9: =VLOOKUP(D9,'Z0000002-502653 BOM triển khai'!$D$3:$K$43,8,0) -> Chốt cài | H9: =C9*$H$1 -> 12
B10: S08 | C10: 12 | D10: STWN20 | E10: =VLOOKUP(D10,'Z0000002-502653 BOM triển khai'!$D$3:$J$43,2,0) | F10: 2.0 X 26.0 X 24.0 | G10: =VLOOKUP(D10,'Z0000002-502653 BOM triển khai'!$D$3:$K$43,8,0) -> Phanh trục | H10: =C10*$H$1 -> 24
B11: S09 | C11: 1 | D11: C1609-24-P-00154 | E11: =VLOOKUP(D11,'Z0000002-502653 BOM triển khai'!$D$3:$J$43,2,0) -> SUS304 | F11: 601.0 X 21.0 X 20.0 | G11: =VLOOKUP(D11,'Z0000002-502653 BOM triển khai'!$D$3:$K$43,8,0) -> TT | H11: =C11*$H$1 -> 2
B12: S10 | C12: 1 | D12: C1609-24-P-00395 | E12: =VLOOKUP(D12,'Z0000002-502653 BOM triển khai'!$D$3:$J$43,2,0) -> SUS304 | F12: 570.0 X 21.0 X 20.0 | G12: =VLOOKUP(D12,'Z0000002-502653 BOM triển khai'!$D$3:$K$43,8,0) -> TT | H12: =C12*$H$1 -> 2
B13: S11 | C13: 8 | D13: B6203ZZ | E13: =VLOOKUP(D13,'Z0000002-502653 BOM triển khai'!$D$3:$J$43,2,0) -> Vòng bi B6203ZZ --> đổi sang C-E6203ZZ | F13: 12.0 X 40.0 X 40.0 | G13: =VLOOKUP(D13,'Z0000002-502653 BOM triển khai'!$D$3:$K$43,8,0) -> VB | H13: =C13*$H$1 -> 16
B14: S12 | C14: 3 | D14: C1609-24-P-00394 | E14: =VLOOKUP(D14,'Z0000002-502653 BOM triển khai'!$D$3:$J$43,2,0) -> Acetal black | F14: 750.0 X 15.0 X 20.0 | G14: =VLOOKUP(D14,'Z0000002-502653 BOM triển khai'!$D$3:$K$43,8,0) -> GTAM | H14: =C14*$H$1 -> 6
B15: S13 | C15: 3 | D15: C1609-24-P-00393 | E15: =VLOOKUP(D15,'Z0000002-502653 BOM triển khai'!$D$3:$J$43,2,0) -> SUS304 | F15: 750.0 X 5.0 X 20.0 | G15: =VLOOKUP(D15,'Z0000002-502653 BOM triển khai'!$D$3:$K$43,8,0) -> Vitech | H15: =C15*$H$1 -> 6
... B25: S23 | C25: 2 | D25: C1609-24-P-00436 | E25: =VLOOKUP(D25,'Z0000002-502653 BOM triển khai'!$D$3:$J$43,2,0) -> SUS304 --> đổi sang AL6061, anode màu xám bạc | F25: 30.0 X 110.0 X 49.0 | G25: =VLOOKUP(D25,'Z0000002-502653 BOM triển khai'!$D$3:$K$43,8,0) -> GTAM | H25: =C25*$H$1 -> 4
B26: S24 | C26: 6 | D26: HTPA32S5M150-A-N20-FC52.0_b | E26: =VLOOKUP(D26,'Z0000002-502653 BOM triển khai'!$D$3:$J$43,2,0) -> HTPA32S5M150-A-N20-FC52.0 | F26: 22.0 X 52.0 X 52.0 | G26: =VLOOKUP(D26,'Z0000002-502653 BOM triển khai'!$D$3:$K$43,8,0) -> UP | H26: =C26*$H$1 -> 12 | I26: ='Z0000002-502653 BOM triển khai'!M26 -> dđã nhận đủ
B27: S25 | C27: 12 | D27: SET-SCREW6-5 | E27: =VLOOKUP(D27,'Z0000002-502653 BOM triển khai'!$D$3:$J$43,2,0) | F27: 5.0 X 6.0 X 6.0 | G27: =VLOOKUP(D27,'Z0000002-502653 BOM triển khai'!$D$3:$K$43,8,0) -> Vít trí | H27: =C27*$H$1 -> 24
B28: S26 | C28: 6 | D28: C1609-24-P-00422 | E28: =VLOOKUP(D28,'Z0000002-502653 BOM triển khai'!$D$3:$J$43,2,0) -> SUS304 --> đổi sang AL6061, anode màu xám bạc | F28: 15.0 X 35.0 X 30.0 | G28: =VLOOKUP(D28,'Z0000002-502653 BOM triển khai'!$D$3:$K$43,8,0) -> GTAM | H28: =C28*$H$1 -> 12
B29: S27 | C29: 3 | D29: C1609-24-P-00423 copy | E29: =VLOOKUP(D29,'Z0000002-502653 BOM triển khai'!$D$3:$J$43,2,0) -> SUS304 | F29: 20.0 X 30.0 X 49.0 | G29: =VLOOKUP(D29,'Z0000002-502653 BOM triển khai'!$D$3:$K$43,8,0) -> CG | H29: =C29*$H$1 -> 6
B30: S28 | C30: 6 | D30: C1609-24-P-00420 | E30: =VLOOKUP(D30,'Z0000002-502653 BOM triển khai'!$D$3:$J$43,2,0) -> SUS304 | F30: 10.0 X 10.0 X 107.0 | G30: TIE | H30: =C30*$H$1 -> 12 | I30: chưa có data gửi NCC
B31: S29 | C31: 6 | D31: C1609-24-P-00396 | E31: =VLOOKUP(D31,'Z0000002-502653 BOM triển khai'!$D$3:$J$43,2,0) -> SUS304 | F31: 18.0 X 40.0 X 8.0 | G31: =VLOOKUP(D31,'Z0000002-502653 BOM triển khai'!$D$3:$K$43,8,0) -> Vitech | H31: =C31*$H$1 -> 12
B32: S30 | C32: 3 | D32: Part93 | E32: =VLOOKUP(D32,'Z0000002-502653 BOM triển khai'!$D$3:$J$43,2,0) -> SUS304 | F32: 3.0 X 75.0 X 61.0 | G32: =VLOOKUP(D32,'Z0000002-502653 BOM triển khai'!$D$3:$K$43,8,0) -> CG | H32: =C32*$H$1 -> 6
B33: S31 | C33: 2 | D33: Solid1_11 | E33: =VLOOKUP(D33,'Z0000002-502653 BOM triển khai'!$D$3:$J$43,2,0) -> SUS304, trục lục giác | F33: 19.0 X 16.0 X 601.0 | G33: =VLOOKUP(D33,'Z0000002-502653 BOM triển khai'!$D$3:$K$43,8,0) -> Vitech | H33: =C33*$H$1 -> 4
B34: S32 | C34: 4 | D34: Solid2_4 | E34: =VLOOKUP(D34,'Z0000002-502653 BOM triển khai'!$D$3:$J$43,2,0) -> Vòng đệm | F34: 3.0 X 24.0 X 24.0 | G34: =VLOOKUP(D34,'Z0000002-502653 BOM triển khai'!$D$3:$K$43,8,0) -> Bulong/ đệm | H34: =C34*$H$1 -> 8
B35: S33 | C35: 4 | D35: Solid2_5 | E35: =VLOOKUP(D35,'Z0000002-502653 BOM triển khai'!$D$3:$J$43,2,0) -> Vòng đệm | F35: 12.0 X 21.0 X 19.0 | G35: =VLOOKUP(D35,'Z0000002-502653 BOM triển khai'!$D$3:$K$43,8,0) -> Bulong/ đệm | H35: =C35*$H$1 -> 8
B36: S34 | C36: 2 | D36: HTPA20S5M150-A-N12_b | E36: =VLOOKUP(D36,'Z0000002-502653 BOM triển khai'!$D$3:$J$43,2,0) -> HTPA20S5M150-A-N12 | F36: 22.0 X 36.0 X 36.0 | G36: =VLOOKUP(D36,'Z0000002-502653 BOM triển khai'!$D$3:$K$43,8,0) -> UP | H36: =C36*$H$1 -> 4 | I36: =I26 -> dđã nhận đủ
B37: S35 | C37: 4 | D37: SET-SCREW4-3 | E37: =VLOOKUP(D37,'Z0000002-502653 BOM triển khai'!$D$3:$J$43,2,0) | F37: 3.0 X 4.0 X 4.0 | G37: =VLOOKUP(D37,'Z0000002-502653 BOM triển khai'!$D$3:$K$43,8,0) -> Vít trí | H37: =C37*$H$1 -> 8
B38: S36 | C38: 1 | D38: C1609-24-P-00390 | E38: =VLOOKUP(D38,'Z0000002-502653 BOM triển khai'!$D$3:$J$43,2,0) -> Mica trong | F38: 90.0 X 160.0 X 3.0 | G38: =VLOOKUP(D38,'Z0000002-502653 BOM triển khai'!$D$3:$K$43,8,0) -> GTAM | H38: =C38*$H$1 -> 2
B39: S37 | C39: 1 | D39: C1609-24-P-00389 | E39: =VLOOKUP(D39,'Z0000002-502653 BOM triển khai'!$D$3:$J$43,2,0) -> SUS304 | F39: 90.0 X 160.0 X 30.0 | G39: =VLOOKUP(D39,'Z0000002-502653 BOM triển khai'!$D$3:$K$43,8,0) -> CG | H39: =C39*$H$1 -> 2
B40: S38 | C40: 1 | D40: C1609-24-P-00388 | E40: =VLOOKUP(D40,'Z0000002-502653 BOM triển khai'!$D$3:$J$43,2,0) -> #N/A | F40: 90.0 X 160.0 X 5.0 | G40: ='Z0000002-502653 BOM triển khai'!K32 -> Vitech | H40: =C40*$H$1 -> 2
B41: S39 | C41: 1 | D41: HTBN300S5M-150_info-1-20-20 | E41: =VLOOKUP(D41,'Z0000002-502653 BOM triển khai'!$D$3:$J$43,2,0) -> HTBN300S5M-150, đổi sang C-HTBN300S5M-150 | F41: 134.0 X 34.0 X 15.0 | G41: =VLOOKUP(D41,'Z0000002-502653 BOM triển khai'!$D$3:$K$43,8,0) -> MI | H41: =C41*$H$1 -> 2 | I41: =I3 -> ducpt đã nhận hàng 27/3
B42: S40 | C42: 1 | D42: S9KB18B | E42: =VLOOKUP(D42,'Z0000002-502653 BOM triển khai'!$D$3:$J$43,2,0) | F42: 90.0 X 90.0 X 75.0 | G42: =VLOOKUP(D42,'Z0000002-502653 BOM triển khai'!$D$3:$K$43,8,0) -> SPG | H42: =C42*$H$1 -> 2 | I42: đã báo a VA đặt hàng
B43: S41 | C43: 1 | D43: S9I40GX-V12CE | E43: =VLOOKUP(D43,'Z0000002-502653 BOM triển khai'!$D$3:$J$43,2,0) | F43: 135.0 X 90.0 X 92.0 | G43: =VLOOKUP(D43,'Z0000002-502653 BOM triển khai'!$D$3:$K$43,8,0) -> SPG | H43: =C43*$H$1 -> 2 | I43: =I42 -> đã báo a VA đặt hàng
H44: =C44*$H$1 -> 0
G47: ='Z0000002-502653 BOM triển khai'!L46 -> AL Profile | H47: ='Z0000002-502653 BOM triển khai'!M46 -> 10/4 đã nhận hàng
G48: ='Z0000002-502653 BOM triển khai'!L47 -> Bulong/ đệm | H48: ='Z0000002-502653 BOM triển khai'!M47 -> đã tồn kho sẵn
G49: ='Z0000002-502653 BOM triển khai'!L48 -> Phanh trục | H49: ='Z0000002-502653 BOM triển khai'!M48 -> đã tồn kho sẵn
G50: ='Z0000002-502653 BOM triển khai'!L49 -> CG | H50: ='Z0000002-502653 BOM triển khai'!M49 -> Nguyện đặt NCC nào đó
G51: ='Z0000002-502653 BOM triển khai'!L50 -> GTAM | H51: ='Z0000002-502653 BOM triển khai'!M50 -> 0
...

Sheet Material&Process
B2: Loại vật liệu | C2: Tên vật liệu tiếng Anh | D2: Tên tiếng Việt | E2: Giá/kg | H2: Tên công đoạn tiếng Anh | I2: Tên tiếng Việt | J2: Giá/hr
A3: 1.51 | B3: POM | C3: POM | D3: POM Thường | E3: 125000 | H3: MCT | J3: 200000
C4: POM ESD BLACK | D4: POM chống tĩnh điện (đen) | E4: 300000 | H4: Wire cutting | I4: Cắt dây | J4: 150000
C5: POM ESD WHITE | D5: POM chống tĩnh điện (trắng) | E5: 310000 | H5: Milling | I5: Phay | J5: 200000
A6: 1.51 | B6: PB108 | C6: PB108 | D6: PB108 thường | E6: 185000 | H6: Drilling | I6: Khoan | J6: 200000
C7: PB108 ESD Black | D7: PB108 chống tĩnh điện (đen) | E7: 312000 | H7: Lathe | I7: Tiện | J7: 200000
C8: PB108 ESD White | D8: PB108 chống tĩnh điện (trắng) | E8: 322000 | H8: Grinding | I8: Mài
B9: PM107 | C9: PM107 | D9: PM107-B Chống tĩnh điện | H9: Laser
B10: MC501 | C10: MC501 | D10: Nhựa MC501 Chống Tĩnh Điện | H10: Urethane
A11: 1.42 | B11: PVC | C11: PVC | D11: PVC Thường | E11: 72000 | H11: Sanding | I11: Xử lý bề mặt phun bi,cát
C12: PVC ESD | D12: PVC chống tĩnh điện | H12: Measuare
A13: 1.2 | B13: URETHANE | C13: URETHANE | D13: URETHANE Thường | E13: 120000 | H13: Assembly | I13: Lắp ráp | J13: 200000
C14: URETHANE ESD | D14: URETHANE chống tĩnh điện | H14: Anodizing | J14: 115đ/cm2
C15: URETHANE 50 | H15: Packing | I15: Đóng gói
C16: URETHANE 70 | H16: Test | I16: Bending, test…
C17: URETHANE 90 | E17: 250000 | H17: Coating
A18: 2.3 | B18: TEFLON | C18: TEFLON | D18: TEFLON Thường | E18: 285000 | H18: Mold
C19: TEFLON ESD | D19: TEFLON chống tĩnh điện | H19: Heating Silicon
A20: 1.51 | B20: BAKELITE | C20: BAKELITE | D20: BAKELITE Thường | E20: 100000 | H20: Plating
C21: BAKELITE ESD | D21: BAKELITE chống tĩnh điện | E21: 114000 | H21: HRC | I21: Tôi Nhiệt
B22: MIKA | C22: MIKA | D22: MICA Thường | H22: DLC
C23: MIKA ESD | D23: MICA chống tĩnh điện
B24: PC | C24: PC | D24: PC thường | E24: 178000
C25: PC ESD | D25: PC chống tĩnh điện
C26: PC GF20
A27: 1.52 | B27: PEEK | C27: PEEK | D27: PEEK | E27: 2600000
B28: ULTEM | C28: ULTEM | D28: UL TEM thường
C29: ULTEM 1000 | D29: UL TEM 1000
B30: ALUMINIUM | C30: AL6061 | D30: AL6061 | E30: 140000
C31: AL7075 | D31: AL7075
C32: AL5052 | D32: AL5052
A33: 8.96 | B33: Copper (CU) | C33: CU Brass | D33: Cu (Đồng) Vàng, đồng thau | E33: 320000
C34: CU Copper | D34: Cu (Đồng) Đỏ
C35: CU Bronze | D35: Cu (Đồng) Xám, Đen
B36: STEEL | C36: S45C | D36: S45C Thép | E36: 60000
C37: SK4 | D37: SK4
C38: SK5 | D38: SK5 | E38: 225000
C39: SKH51 | D39: SKH51
C40: SM20C | D40: SM20C
C41: SM45C | D41: SM45C
...
