Workbook

Sheet Z0000002-238846 BOM trien k hai
A1: Z0000002-238846_ 18_19. CV input Tray BOM | G1: SL ( set ) | H1: 6 | I1: [4pcs/cụm* 6=24 pcs]
A2: Image | B2: ID Number | C2: Quantity | D2: Standard Number | E2: Sub Category | F2: NCC | G2: Visible Part Size | H2: SL | I2: giao 50% ngày 5/4 | J2: giao 50% còn lại ngày 15/4 | O2: Material
B3: V01 | C3: 2 | D3: 18.1_Mnf_AL6061_1_MIR3 | E3: AL6061, anode màu đen | F3: GTAM | G3: 90.0 X 125.0 X 10.0 | H3: =C3*$H$1 -> 12 | I3: đã đặt phôi, có thể làm xong trc 5/4
B4: V02 | C4: 2 | D4: 18.2_Mnf_AL6061_1_MIR3 | E4: =E3 -> AL6061, anode màu đen | F4: =F3 -> GTAM | G4: 50.0 X 95.0 X 10.0 | H4: =C4*$H$1 -> 12 | I4: =I3 -> đã đặt phôi, có thể làm xong trc 5/4
B5: V03 | C5: 1 | D5: 18.3_Mnf_AL6061_1_MIR3 | E5: =E4 -> AL6061, anode màu đen | F5: =F4 -> GTAM | G5: 50.0 X 10.0 X 243.0 | H5: =C5*$H$1 -> 6 | I5: =I4 -> đã đặt phôi, có thể làm xong trc 5/4
B6: V04 | C6: 2 | D6: 19.1_Mnf_Al6061_1 | E6: =E5 -> AL6061, anode màu đen | F6: =F5 -> GTAM | G6: 50.0 X 10.0 X 230.0 | H6: =C6*$H$1 -> 12 | I6: =I5 -> đã đặt phôi, có thể làm xong trc 5/4
B7: V05 | C7: 2 | D7: 18.12_Mnf_SUS304_1_MIR1 | E7: SUS304 điện hóa/ S45C mạ Nikel, có lăn nhám | F7: TAT | G7: 20.0 X 34.0 X 34.0 | H7: =C7*$H$1 -> 12 | I7: Ng đã đặt NCC mới cho đủ 84CV
B8: V06 | C8: 4 | D8: 18.13_688AZZ_NSK_1_MIR1 | E8: vòng bi 688AZZ | F8: VB | G8: 5.0 X 16.0 X 16.0 | H8: =C8*$H$1 -> 24 | I8: đã đặt hàng CN
B9: V07 | C9: 1 | D9: SPG S6I06GX-V12_MIR3 | E9: động cơ S6I06GX-V12/ bộ điều khiển tốc độ đi kèm | F9: SPG | G9: 88.0 X 60.0 X 62.0 | H9: =C9*$H$1 -> 6 | I9: đã báo đặt hàng
B10: V08 | C10: 1 | D10: Hộp số SPG S6KA30B_MIR3 | E10: kiu | F10: =F9 -> SPG | G10: 73.0 X 60.0 X 60.0 | H10: =C10*$H$1 -> 6 | I10: =I9 -> đã báo đặt hàng
B11: V09 | C11: 2 | D11: 6.6_HTPA25S3M150-A-N8_1_MIR3 | E11: HTPA25S3M150-A-N8 | F11: UP | G11: 21.0 X 28.0 X 28.0 | H11: =C11*$H$1 -> 12 | I11: đã nhận hàng 30/3
B12: V10 | C12: 2 | D12: 6.7_KES3-12_1_MIR3 | E12: chốt cài KES3-12 | F12: Then cài | G12: 12.0 X 3.0 X 3.0 | H12: =C12*$H$1 -> 12 | I12: đã tồn kho sẵn
B13: V11 | C13: 1 | D13: 21.11_Mnf_SUS304_1_MIR3 | E13: SUS304 có điện hóa | F13: CG | G13: 90.0 X 111.0 X 28.0 | H13: =C13*$H$1 -> 6 | I13: đã chốt làm MAH toàn bộ, có hàng trc 4/4
B14: V12 | C14: 1 | D14: 21.13_HTBN225S3M-150_info-1-25-25_MIR3 | E14: HTBN225S3M-150 --> đổi sang C-HTBN225S3M-150 | F14: MI | G14: 100.0 X 25.0 X 15.0 | H14: =C14*$H$1 -> 6 | I14: 31/3 và 3/4 nhận đủ hàng
B15: V13 | C15: 1 | D15: 21.12_Mnf_PC ESD trong_1_MIR3 | E15: Mica trong | F15: GTAM | G15: 6.0 X 109.0 X 86.0 | H15: =C15*$H$1 -> 6 | I15: =I5 -> đã đặt phôi, có thể làm xong trc 5/4
B16: V14 | C16: 1 | D16: 21.15_Mnf_Al6061_1_MIR3 | E16: =E3 -> AL6061, anode màu đen | F16: =F15 -> GTAM | G16: 90.0 X 73.0 X 10.0 | H16: =C16*$H$1 -> 6 | I16: =I15 -> đã đặt phôi, có thể làm xong trc 5/4
B17: V15 | C17: 1 | D17: 20.1_Mnf_Al6061_1_MIR3 | E17: =E16 -> AL6061, anode màu đen | F17: =F16 -> GTAM | G17: 10.0 X 94.0 X 58.0 | H17: =C17*$H$1 -> 6 | I17: =I16 -> đã đặt phôi, có thể làm xong trc 5/4
B18: V16 | C18: 1 | D18: 20.2_Mnf_Al6061_1_MIR3 | E18: =E17 -> AL6061, anode màu đen | F18: =F17 -> GTAM | G18: 8.0 X 69.0 X 95.0 | H18: =C18*$H$1 -> 6 | I18: =I17 -> đã đặt phôi, có thể làm xong trc 5/4
B19: V17 | C19: 1 | D19: 20.4_Mnf_SUS304_1_MIR3 | E19: =E13 -> SUS304 có điện hóa | F19: CG | G19: 62.0 X 61.0 X 79.0 | H19: =C19*$H$1 -> 6 | I19: =I13 -> đã chốt làm MAH toàn bộ, có hàng trc 4/4
B20: V18 | C20: 1 | D20: 20.3_Mnf_Al6061_1_MIR3 | E20: =E18 -> AL6061, anode màu đen | F20: GTAM | G20: 10.0 X 58.0 X 115.0 | H20: =C20*$H$1 -> 6 | I20: =I18 -> đã đặt phôi, có thể làm xong trc 5/4
B21: V19 | C21: 1 | D21: 20.5_Mnf_SUS304_1_MIR3 | E21: =E19 -> SUS304 có điện hóa | F21: =F19 -> CG | G21: 41.0 X 31.0 X 94.0 | H21: =C21*$H$1 -> 6 | I21: =I13 -> đã chốt làm MAH toàn bộ, có hàng trc 4/4
B22: V20 | C22: 1 | D22: 18.091024_AL6061_01_MIR1 | E22: =E20 -> AL6061, anode màu đen | F22: =F20 -> GTAM | G22: 10.0 X 30.0 X 26.0 | H22: =C22*$H$1 -> 6 | I22: =I20 -> đã đặt phôi, có thể làm xong trc 5/4
B23: V21 | C23: 1 | D23: 18.10_Mnf_SUS304_1_MIR1 | E23: SUS304 điện hóa/ S45C mạ Nikel | F23: =F7 -> TAT | G23: 12.0 X 273.0 X 12.0 | H23: =C23*$H$1 -> 6 | I23: =I7 -> Ng đã đặt NCC mới cho đủ 84CV
B24: V22 | C24: 2 | D24: 18.11_Mnf_SUS304_1_MIR1 | E24: =E23 -> SUS304 điện hóa/ S45C mạ Nikel | F24: =F23 -> TAT | G24: 20.0 X 34.0 X 34.0 | H24: =C24*$H$1 -> 12 | I24: =I23 -> Ng đã đặt NCC mới cho đủ 84CV
B25: V23 | C25: 1 | D25: 18.4_Mnf_Al6061_1_MIR2 | E25: =E16 -> AL6061, anode màu đen | F25: =F17 -> GTAM | G25: 335.0 X 10.0 X 39.0 | H25: =C25*$H$1 -> 6 | I25: =I22 -> đã đặt phôi, có thể làm xong trc 5/4
B26: V24 | C26: 1 | D26: 18.5_Mnf_Al6061_1_MIR1 | E26: =E17 -> AL6061, anode màu đen | F26: =F25 -> GTAM | G26: 10.0 X 30.0 X 30.0 | H26: =C26*$H$1 -> 6 | I26: =I25 -> đã đặt phôi, có thể làm xong trc 5/4
B27: V25 | C27: 1 | D27: 18.6_Mnf_SUS304_1_MIR2 | E27: =E21 -> SUS304 có điện hóa | F27: =F19 -> CG | G27: 335.0 X 25.0 X 32.0 | H27: =C27*$H$1 -> 6 | I27: =I19 -> đã chốt làm MAH toàn bộ, có hàng trc 4/4
B28: V26 | C28: 2 | D28: 18.7_Mnf_SUS304_1_MIR1 | E28: =E27 -> SUS304 có điện hóa | F28: =F27 -> CG | G28: 256.0 X 57.0 X 18.0 | H28: =C28*$H$1 -> 12 | I28: =I27 -> đã chốt làm MAH toàn bộ, có hàng trc 4/4
B29: V27 | C29: 2 | D29: 18.8_Belt PU chống tĩnh điện_MIR1 | E29: belt PU chống tĩnh điện, màu đen, dày 1.5mm, bản rộng 20mm, chu vi 680mm ( đo mép trong 686mm) | F29: Yongli | G29: 329.0 X 20.0 X 33.0 | H29: =C29*$H$1 -> 12 | I29: đã nhận hàng
B30: V28 | C30: 1 | D30: 18.9_Mnf_SUS304_1_MIR1 | E30: SUS304 điện hóa/ S45C mạ Nikel | F30: =F24 -> TAT | G30: 260.0 X 10.0 X 10.0 | H30: =C30*$H$1 -> 6 | I30: =I24 -> Ng đã đặt NCC mới cho đủ 84CV
B31: V29 | C31: 2 | D31: 18.STWN8_MIR1 | E31: Phanh trục STWN8 | F31: PT- Phanh trục | G31: 1.0 X 13.0 X 10.0 | H31: =C31*$H$1 -> 12 | I31: tồn kho sẵn
B32: V30 | C32: 2 | D32: 21.2_Mnf_Al6061_1_MIR3 | E32: =E3 -> AL6061, anode màu đen | F32: =F3 -> GTAM | G32: 10.0 X 30.0 X 10.0 | H32: =C32*$H$1 -> 12 | I32: =I26 -> đã đặt phôi, có thể làm xong trc 5/4
B33: V31 | C33: 2 | D33: 21.8_B6000ZZ_1_MIR3 | E33: B6000ZZ | F33: VB | G33: 8.0 X 26.0 X 26.0 | H33: =C33*$H$1 -> 12 | I33: =I8 -> đã đặt hàng CN
B34: V32 | C34: 1 | D34: 18.6_Mnf_SUS304_1_MIR_MIR1 | E34: =E27 -> SUS304 có điện hóa | F34: =F27 -> CG | G34: 335.0 X 25.0 X 32.0 | H34: =C34*$H$1 -> 6 | I34: =I28 -> đã chốt làm MAH toàn bộ, có hàng trc 4/4
B35: V33 | C35: 1 | D35: 18.4_Mnf_Al6061_1_MIR_MIR1 | E35: =E25 -> AL6061, anode màu đen | F35: =F25 -> GTAM | G35: 335.0 X 10.0 X 39.0 | H35: =C35*$H$1 -> 6 | I35: =I32 -> đã đặt phôi, có thể làm xong trc 5/4
B36: V34 | C36: 4 | D36: 18.1_Mnf_AL6061_1 | E36: =E3 -> AL6061, anode màu đen | F36: =F3 -> GTAM | G36: 90.0 X 125.0 X 10.0 | H36: =C36*$H$1 -> 24 | I36: =I35 -> đã đặt phôi, có thể làm xong trc 5/4
B37: V35 | C37: 4 | D37: 18.2_Mnf_AL6061_1 | E37: =E4 -> AL6061, anode màu đen | F37: =F4 -> GTAM | G37: 50.0 X 95.0 X 10.0 | H37: =C37*$H$1 -> 24 | I37: =I36 -> đã đặt phôi, có thể làm xong trc 5/4
B38: V36 | C38: 2 | D38: 18.3_Mnf_AL6061_1 | E38: =E5 -> AL6061, anode màu đen | F38: =F5 -> GTAM | G38: 50.0 X 10.0 X 243.0 | H38: =C38*$H$1 -> 12 | I38: =I37 -> đã đặt phôi, có thể làm xong trc 5/4
B39: V37 | C39: 4 | D39: 18.12_Mnf_SUS304_1 | E39: =E7 -> SUS304 điện hóa/ S45C mạ Nikel, có lăn nhám | F39: =F24 -> TAT | G39: 20.0 X 34.0 X 34.0 | H39: =C39*$H$1 -> 24 | I39: =I30 -> Ng đã đặt NCC mới cho đủ 84CV
B40: V38 | C40: 8 | D40: 18.13_688AZZ_NSK_1 | E40: =E8 -> vòng bi 688AZZ | F40: =F8 -> VB | G40: 5.0 X 16.0 X 16.0 | H40: =C40*$H$1 -> 48 | I40: =I33 -> đã đặt hàng CN
...

Sheet Z0000002-238847 BOM trien khai
A1: Z0000002-238847 BOM | G1: SL | H1: 9 | I1: [4pcs/cụm* 9=36 pcs]
A2: Image | B2: ID Number | C2: Quantity | D2: Standard Number | E2: Sub Category | F2: NCC | G2: Visible Part Size | I2: note 1 | O2: Material
B3: X01 | C3: 1 | D3: SPG S6I06GX-V12_MIR2 | E3: động cơ SPG S6I06GX-V12/ bộ điều khiển tốc độ đi kèm | F3: SPG | G3: 88.0 X 60.0 X 62.0 | H3: =$H$1*C3 -> 9
B4: X02 | C4: 1 | D4: Hộp số SPG S6KA30B_MIR2 | E4: Hộp số SPG S6KA30B | F4: =F3 -> SPG | G4: 73.0 X 60.0 X 60.0 | H4: =$H$1*C4 -> 9
B5: X03 | C5: 2 | D5: 6.6_HTPA25S3M150-A-N8_1_MIR2 | E5: HTPA25S3M150-A-N8 | F5: UP | G5: 21.0 X 28.0 X 28.0 | H5: =$H$1*C5 -> 18 | I5: ='Z0000002-238846 BOM trien k hai'!G109 -> đã nhận hàng 30/3
B6: X04 | C6: 2 | D6: 6.7_KES3-12_1_MIR2 | E6: chốt cài KES3-12 | F6: Then cài | G6: 12.0 X 3.0 X 3.0 | H6: =$H$1*C6 -> 18 | I6: đang check tồn
B7: X05 | C7: 1 | D7: 21.11_Mnf_SUS304_1_MIR2 | E7: SUS304 điện hóa | F7: CG | G7: 90.0 X 111.0 X 28.0 | H7: =$H$1*C7 -> 9
B8: X06 | C8: 1 | D8: 21.13_HTBN225S3M-150_info-1-25-25_MIR2 | E8: HTBN225S3M-150 --> đổi sang C-HTBN225S3M-150 | F8: MI | G8: 100.0 X 25.0 X 15.0 | H8: =$H$1*C8 -> 9 | I8: ='Z0000002-238846 BOM trien k hai'!G105 -> 31/3 và 3/4 nhận đủ hàng
B9: X07 | C9: 1 | D9: 21.12_Mnf_PC ESD trong_1_MIR2 | E9: Mica trong | F9: GTAM | G9: 6.0 X 109.0 X 86.0 | H9: =$H$1*C9 -> 9
B10: X08 | C10: 1 | D10: 21.15_Mnf_Al6061_1_MIR2 | E10: AL6061, anode màu đen | F10: =F9 -> GTAM | G10: 90.0 X 73.0 X 10.0 | H10: =$H$1*C10 -> 9
B11: X09 | C11: 1 | D11: 20.1_Mnf_Al6061_1_MIR2 | E11: =E10 -> AL6061, anode màu đen | F11: =F10 -> GTAM | G11: 10.0 X 94.0 X 58.0 | H11: =$H$1*C11 -> 9
B12: X10 | C12: 1 | D12: 20.2_Mnf_Al6061_1_MIR2 | E12: =E23 -> AL6061, anode màu đen | F12: =F23 -> GTAM | G12: 8.0 X 69.0 X 95.0 | H12: =$H$1*C12 -> 9
B13: X11 | C13: 1 | D13: 20.4_Mnf_SUS304_1_MIR2 | E13: SUS304 điện hóa | F13: CG | G13: 62.0 X 61.0 X 79.0 | H13: =$H$1*C13 -> 9
B14: X12 | C14: 1 | D14: 20.3_Mnf_Al6061_1_MIR2 | E14: =E23 -> AL6061, anode màu đen | F14: =F23 -> GTAM | G14: 10.0 X 58.0 X 115.0 | H14: =$H$1*C14 -> 9
B15: X13 | C15: 1 | D15: 20.5_Mnf_SUS304_1_MIR2 | E15: SUS304 điện hóa | F15: CG | G15: 41.0 X 31.0 X 94.0 | H15: =$H$1*C15 -> 9
B16: X14 | C16: 2 | D16: 17.0.B6900ZZ_230824_MIR_MIR1 | E16: vòng bi B6900ZZ | F16: VB | G16: 6.0 X 22.0 X 22.0 | H16: =$H$1*C16 -> 18 | I16: ='Z0000002-238846 BOM trien k hai'!G110 -> hàng đã về
B17: X15 | C17: 2 | D17: 18.1_Mnf_AL6061_1_MIR2 | E17: =E23 -> AL6061, anode màu đen | F17: =F23 -> GTAM | G17: 90.0 X 125.0 X 10.0 | H17: =$H$1*C17 -> 18
B18: X16 | C18: 2 | D18: 18.2_Mnf_AL6061_1_MIR2 | E18: =E23 -> AL6061, anode màu đen | F18: =F23 -> GTAM | G18: 50.0 X 95.0 X 10.0 | H18: =$H$1*C18 -> 18
B19: X17 | C19: 1 | D19: 18.3_Mnf_AL6061_1_MIR2 | E19: =E23 -> AL6061, anode màu đen | F19: =F23 -> GTAM | G19: 50.0 X 10.0 X 243.0 | H19: =$H$1*C19 -> 9
B20: X18 | C20: 1 | D20: 21.10_Belt PU chong tinh dien_1_MIR1 | E20: belt PU chống tĩnh điện, màu đen, dày 1.5mm, bản rộng 226mm, chu vi 600mm ( đo mép trong 606mm, đai căn chỉnh ở giữa) | F20: Yongli | G20: 289.0 X 226.0 X 33.0 | H20: =$H$1*C20 -> 9 | I20: ='[1]Z0000002-238846 BOM trien k hai'!$I$29 -> đã chốt đặt hàng
B21: X19 | C21: 1 | D21: 21.1_Mnf_Al6061_1_MIR2 | E21: =E23 -> AL6061, anode màu đen | F21: =F23 -> GTAM | G21: 295.0 X 10.0 X 39.0 | H21: =$H$1*C21 -> 9
B22: X20 | C22: 1 | D22: 21.1_Mnf_Al6061_1_MIR_MIR1 | E22: =E21 -> AL6061, anode màu đen | F22: =F21 -> GTAM | G22: 295.0 X 10.0 X 39.0 | H22: =$H$1*C22 -> 9
B23: X21 | C23: 2 | D23: 21.2_Mnf_Al6061_1_MIR2 | E23: AL6061, anode màu đen | F23: GTAM | G23: 10.0 X 30.0 X 10.0 | H23: =$H$1*C23 -> 18
B24: X22 | C24: 1 | D24: 21.3_Mnf_SUS304_1_MIR1 | E24: SUS304 điện hóa | F24: CG | G24: 216.0 X 230.0 X 18.0 | H24: =$H$1*C24 -> 9
B25: X23 | C25: 1 | D25: 21.4_Mnf_SUS304_1_MIR2 | E25: SUS304 điện hóa | F25: CG | G25: 295.0 X 25.0 X 32.0 | H25: =$H$1*C25 -> 9
B26: X24 | C26: 1 | D26: 21.4_Mnf_SUS304_1_MIR_MIR1 | E26: =E25 -> SUS304 điện hóa | F26: =F25 -> CG | G26: 295.0 X 25.0 X 32.0 | H26: =$H$1*C26 -> 9
B27: X25 | C27: 1 | D27: 21.6_Mnf_SUS304_1_MIR1 | E27: ct trục, SUS304 điện hóa/ S45C mạ nikel | F27: PG | G27: 10.0 X 268.0 X 10.0 | H27: =$H$1*C27 -> 9
B28: X26 | C28: 1 | D28: 21.7_Mnf_SUS304_1_MIR1 | E28: ct trục, SUS304 điện hóa/ S45C mạ nikel | F28: PG | G28: 30.0 X 224.0 X 30.0 | H28: =$H$1*C28 -> 9
B29: X27 | C29: 2 | D29: 21.8_B6000ZZ_1_MIR2 | E29: Vòng bi B6000ZZ | F29: VB | G29: 8.0 X 26.0 X 26.0 | H29: =$H$1*C29 -> 18
B30: X28 | C30: 2 | D30: 21.9_STWN10_1_MIR1 | E30: phanh trục STWN10 | F30: PT- Phanh trục | G30: 15.0 X 1.0 X 13.0 | H30: =$H$1*C30 -> 18 | I30: Tồn kho sẵn
B31: X29 | C31: 1 | D31: 21.5_Mnf_SUS304_1_MIR1 | E31: ct trục, SUS304 điện hóa/ S45C mạ nikel | F31: PG | G31: 30.0 X 271.0 X 30.0 | H31: =$H$1*C31 -> 9
B32: X30 | C32: 2 | D32: 21.11_Mnf_SUS304_1 | E32: =E7 -> SUS304 điện hóa | F32: =F7 -> CG | G32: 90.0 X 111.0 X 28.0 | H32: =$H$1*C32 -> 18
B33: X31 | C33: 2 | D33: HI_HTBN225S3M-150_info-1-25-25 | E33: =E8 -> HTBN225S3M-150 --> đổi sang C-HTBN225S3M-150 | F33: =F8 -> MI | G33: 100.0 X 25.0 X 15.0 | H33: =$H$1*C33 -> 18 | I33: =I8 -> 31/3 và 3/4 nhận đủ hàng
B34: X32 | C34: 2 | D34: 21.12_Mnf_PC ESD trong_1 | E34: =E9 -> Mica trong | F34: =F9 -> GTAM | G34: 6.0 X 109.0 X 86.0 | H34: =$H$1*C34 -> 18
B35: X33 | C35: 4 | D35: 6.6_HTPA25S3M150-A-N8_1 | E35: HTPA25S3M150-A-N8 | F35: =F5 -> UP | G35: 21.0 X 28.0 X 28.0 | H35: =$H$1*C35 -> 36 | I35: =I5 -> đã nhận hàng 30/3
B36: X34 | C36: 4 | D36: 6.7_KES3-12_1 | E36: =E6 -> chốt cài KES3-12 | F36: =F6 -> Then cài | G36: 12.0 X 3.0 X 3.0 | H36: =$H$1*C36 -> 36 | I36: ='[1]Z0000002-238846 BOM trien k hai'!$I$80 -> đã tồn kho sẵn
B37: X35 | C37: 2 | D37: SPG S6I06GX-V12 | E37: =E3 -> động cơ SPG S6I06GX-V12/ bộ điều khiển tốc độ đi kèm | F37: =F3 -> SPG | G37: 88.0 X 60.0 X 62.0 | H37: =$H$1*C37 -> 18
B38: X36 | C38: 2 | D38: SPG S6DA30B, đổi sang S6KA30B | E38: =E4 -> Hộp số SPG S6KA30B | F38: =F4 -> SPG | G38: 73.0 X 60.0 X 60.0 | H38: =$H$1*C38 -> 18
B39: X37 | C39: 2 | D39: 21.15_Mnf_Al6061_1 | E39: =E10 -> AL6061, anode màu đen | F39: =F10 -> GTAM | G39: 90.0 X 73.0 X 10.0 | H39: =$H$1*C39 -> 18
B40: X38 | C40: 2 | D40: 20.1_Mnf_Al6061_1 | E40: =E11 -> AL6061, anode màu đen | F40: =F11 -> GTAM | G40: 10.0 X 94.0 X 58.0 | H40: =$H$1*C40 -> 18
...

Sheet Z0000002-238848 BOM trien k hai
A1: Z0000002-238848 Z0000002-238849 _ 6&7.Cụm CV_In Out Set - BOM | G1: SL | H1: 6 | I1: [ 02 pcs/set*6= 12 pcs ]
A2: Image | B2: ID Number | C2: Quantity | D2: Standard Number | E2: Sub Category | F2: NCC | G2: Visible Part Size | I2: note 1 | P2: Material
B3: Y01 | C3: 1 | D3: 0.MF_PB108_8_7_230824 | E3: PB108 màu đen | F3: GTAM | G3: 34.0 X 20.0 X 126.0 | H3: =C3*$H$1 -> 6
B4: Y02 | C4: 26 | D4: 6.Con lăn ED-WS08,Polyurethane Rubber | E4: 0 | F4: Bỏ | G4: 14.0 X 14.0 X 16.0 | H4: =C4*$H$1 -> 156
B5: Y03 | C5: 1 | D5: 7.0.MF_PB108_8_7_230824_MIR1 | E5: =E3 -> PB108 màu đen | F5: =F3 -> GTAM | G5: 34.0 X 20.0 X 126.0 | H5: =C5*$H$1 -> 6
B6: Y04 | C6: 8 | D6: 6.Con lăn ED-WS08,Polyurethane Rubber_MIR1 | E6: 0 | F6: =F4 -> Bỏ | G6: 14.0 X 14.0 X 16.0 | H6: =C6*$H$1 -> 48
B7: Y05 | C7: 2 | D7: 6.0_6000ZZ_NSK | E7: Vòng bi 6000ZZ | F7: VB | G7: 8.0 X 26.0 X 26.0 | H7: =C7*$H$1 -> 12 | I7: ='Z0000002-238847 BOM trien khai'!I74 -> hàng đã về
B8: Y06 | C8: 4 | D8: 6.0_688AZZ_NSK | E8: vòng bi 688AZZ | F8: VB | G8: 5.0 X 16.0 X 16.0 | H8: =C8*$H$1 -> 24 | I8: =I7 -> hàng đã về
B9: Y07 | C9: 1 | D9: 6.0_C-HTBN222S3M-150 | E9: C-HTBN222S3M-150, đổi sang C-HTBN225S3M-150 | F9: MI | G9: 99.0 X 26.0 X 15.0 | H9: =C9*$H$1 -> 6 | I9: =G73 -> 31/3 và 3/4 nhận đủ hàng
B10: Y08 | C10: 2 | D10: 6.0_C-HTPA25S3M150-A-N8 | E10: C-HTPA25S3M150-A-N8 | F10: UP | G10: 21.0 X 28.0 X 28.0 | H10: =C10*$H$1 -> 12 | I10: ='Z0000002-238847 BOM trien khai'!G100 -> đã nhận hàng 30/3
B11: Y09 | C11: 2 | D11: 6.0_KES3-12 | E11: chốt cài KES3-12 | F11: Then cài | G11: 12.0 X 3.0 X 3.0 | H11: =C11*$H$1 -> 12 | I11: đã tồn kho sẵn
B12: Y10 | C12: 1 | D12: 6.0_S6I06G-GX | E12: động cơ S6I06GX-V12/ bộ điều khiển tốc độ đi kèm | F12: SPG | G12: 100.0 X 60.0 X 62.0 | H12: =C12*$H$1 -> 6
B13: Y11 | C13: 1 | D13: 6.0_S6KA15B_1 | E13: Hộp số S6KA15B | F13: =F12 -> SPG | G13: 60.0 X 60.0 X 63.0 | H13: =C13*$H$1 -> 6
B14: Y12 | C14: 2 | D14: 6.1.Mnf_AL6061_03 | E14: AL6061, anode màu đen | F14: GTAM | G14: 10.0 X 30.0 X 10.0 | H14: =C14*$H$1 -> 12
B15: Y13 | C15: 1 | D15: 6.1.Mnf_AL6061_05 | E15: AL6061, anode màu đen | F15: GTAM | G15: 90.0 X 75.0 X 10.0 | H15: =C15*$H$1 -> 6
B16: Y14 | C16: 4 | D16: 6.1_Mnf_AL6061_1 | E16: AL6061, anode màu đen | F16: =F21 -> GTAM | G16: 10.0 X 30.0 X 30.0 | H16: =C16*$H$1 -> 24
B17: Y15 | C17: 2 | D17: 6.3.Mnf_SUS304_03 | E17: SUS304 | F17: LINH | G17: 47.0 X 11.0 X 11.0 | H17: =C17*$H$1 -> 12 | I17: ='Z0000002-238846 BOM trien k hai'!G106 -> Ng đã đặt NCC mới cho đủ 84CV
B18: Y16 | C18: 2 | D18: 6.3.Mnf_SUS304_06 | E18: SUS304 điện hóa/ S45C mạ nikel- có lăn nhám | F18: PG | G18: 20.0 X 34.0 X 34.0 | H18: =C18*$H$1 -> 12 | I18: =I17 -> Ng đã đặt NCC mới cho đủ 84CV
B19: Y17 | C19: 2 | D19: 6.3.Mnf_SUS304_07 | E19: SUS304 điện hóa/ S45C mạ nikel | F19: =F18 -> PG | G19: 20.0 X 34.0 X 34.0 | H19: =C19*$H$1 -> 12 | I19: =I18 -> Ng đã đặt NCC mới cho đủ 84CV
B20: Y18 | C20: 1 | D20: 6.3.Mnf_SUS304_09 | E20: =E35 -> SUS304, điện hóa | F20: CG | G20: 90.0 X 109.0 X 28.0 | H20: =C20*$H$1 -> 6 | I20: =G71 -> đã chốt làm MAH toàn bộ, có hàng trc 4/4
B21: Y19 | C21: 1 | D21: 6.4.Mnf_Clear PC_01 | E21: Mica trong | F21: GTAM | G21: 5.0 X 106.0 X 85.0 | H21: =C21*$H$1 -> 6
B22: Y20 | C22: 2 | D22: 7.0.Belt_233 | E22: belt PU đen, chống tĩnh điện 10^5-10^9, dày 1.5mm, bản rộng 20mm, chu vi 620mm ( đo mép trong 623mm) | F22: Yongli | G22: 20.0 X 34.0 X 297.0 | H22: =C22*$H$1 -> 12 | I22: ='[1]Z0000002-238846 BOM trien k hai'!$I$29 -> đã chốt đặt hàng
B23: Y21 | C23: 2 | D23: 0.MF_AL_25_2_230824 | E23: =E16 -> AL6061, anode màu đen | F23: =F21 -> GTAM | G23: 12.0 X 65.0 X 40.0 | H23: =C23*$H$1 -> 12
B24: Y22 | C24: 1 | D24: 7.1.Mnf_AL6061_01 | E24: =E23 -> AL6061, anode màu đen | F24: =F23 -> GTAM | G24: 10.0 X 34.0 X 305.0 | H24: =C24*$H$1 -> 6
B25: Y23 | C25: 1 | D25: 7.1.Mnf_AL6061_01_180225_MIR | E25: =E24 -> AL6061, anode màu đen | F25: =F24 -> GTAM | G25: 10.0 X 34.0 X 305.0 | H25: =C25*$H$1 -> 6
B26: Y24 | C26: 2 | D26: 7.2.Mnf_PB108_01 | E26: PB108 màu đen | F26: GTAM | G26: 10.0 X 180.0 X 2.0 | H26: =C26*$H$1 -> 12
B27: Y25 | C27: 1 | D27: 7.2.Mnf_PB108_02 | E27: =E26 -> PB108 màu đen | F27: =F26 -> GTAM | G27: 87.0 X 8.0 X 186.0 | H27: =C27*$H$1 -> 6
B28: Y26 | C28: 1 | D28: 7.3.Mnf_SUS304_01 | E28: SUS304, điện hóa | F28: CG | G28: 86.0 X 3.0 X 185.0 | H28: =C28*$H$1 -> 6 | I28: =I20 -> đã chốt làm MAH toàn bộ, có hàng trc 4/4
B29: Y27 | C29: 1 | D29: 7.3.Mnf_SUS304_05 | E29: =E28 -> SUS304, điện hóa | F29: =F28 -> CG | G29: 26.0 X 26.0 X 72.0 | H29: =C29*$H$1 -> 6 | I29: =I28 -> đã chốt làm MAH toàn bộ, có hàng trc 4/4
B30: Y28 | C30: 1 | D30: 7.3.Mnf_SUS304_02 | E30: =E29 -> SUS304, điện hóa | F30: =F29 -> CG | G30: 26.0 X 26.0 X 102.0 | H30: =C30*$H$1 -> 6 | I30: =I29 -> đã chốt làm MAH toàn bộ, có hàng trc 4/4
B31: Y29 | C31: 2 | D31: 7.3.Mnf_SUS304_03 | E31: ct trục, SUS304 điện hóa/ S45C mạ nikel | F31: LINH | G31: 112.0 X 10.0 X 12.0 | H31: =C31*$H$1 -> 12 | I31: =I17 -> Ng đã đặt NCC mới cho đủ 84CV
B32: Y30 | C32: 1 | D32: 7.3.Mnf_SUS304_04 | E32: =E31 -> ct trục, SUS304 điện hóa/ S45C mạ nikel | F32: PG | G32: 152.0 X 13.0 X 13.0 | H32: =C32*$H$1 -> 6 | I32: =I31 -> Ng đã đặt NCC mới cho đủ 84CV
B33: Y31 | C33: 2 | D33: MF_AL_25_3_170225 | E33: =E25 -> AL6061, anode màu đen | F33: =F25 -> GTAM | G33: 25.0 X 62.0 X 40.0 | H33: =C33*$H$1 -> 12
B34: Y32 | C34: 1 | D34: 041024_PB108_01 | E34: =E26 -> PB108 màu đen | F34: =F33 -> GTAM | G34: 351.0 X 35.0 X 20.0 | H34: =C34*$H$1 -> 6
B35: Y33 | C35: 1 | D35: 6.1_Mnf_SUS304_1 | E35: =E28 -> SUS304, điện hóa | F35: =F28 -> CG | G35: 90.0 X 109.0 X 28.0 | H35: =C35*$H$1 -> 6 | I35: =I30 -> đã chốt làm MAH toàn bộ, có hàng trc 4/4
B36: Y34 | C36: 1 | D36: 6.2_Mnf_PC ESD trong_1 | E36: Mica trong | F36: =F34 -> GTAM | G36: 6.0 X 107.0 X 86.0 | H36: =C36*$H$1 -> 6
B37: Y35 | C37: 1 | D37: 6.3_Mnf_Al6061_1 | E37: =E15 -> AL6061, anode màu đen | F37: =F15 -> GTAM | G37: 90.0 X 75.0 X 10.0 | H37: =C37*$H$1 -> 6
B38: Y36 | C38: 1 | D38: 6.4_S6I06GX-V12_1 | E38: =E12 -> động cơ S6I06GX-V12/ bộ điều khiển tốc độ đi kèm | F38: =F12 -> SPG | G38: 100.0 X 60.0 X 62.0 | H38: =C38*$H$1 -> 6
B39: Y37 | C39: 1 | D39: 6.5_S6KA15B_1 | E39: =E13 -> Hộp số S6KA15B | F39: =F13 -> SPG | G39: 60.0 X 60.0 X 63.0 | H39: =C39*$H$1 -> 6
B40: Y38 | C40: 2 | D40: 6.6_HTPA25S3M150-A-N8_1 | E40: HTPA25S3M150-A-N8 | F40: =F10 -> UP | G40: 21.0 X 28.0 X 28.0 | H40: =C40*$H$1 -> 12 | I40: =I10 -> đã nhận hàng 30/3
...

Sheet Z0000002-238851 BOM triển kh ai
A1: Z0000002-238851_13.Cụm tách tray_TOP_ LR_ 02pcs - BOM | G1: SL | H1: 6 | I1: [2pcs/set* 6=12 pcs]
A2: Image | B2: ID Number | C2: Quantity | D2: Standard Number | E2: Sub Category | F2: NCC | G2: Visible Part Size | H2: SL | I2: Note 1 | O2: Material
B3: Z01 | C3: 2 | D3: 13.B6000ZZ#2 | E3: Vòng bi B6000ZZ | F3: VB | G3: 8.0 X 26.0 X 26.0 | H3: =$H$1*C3 -> 12 | I3: đã đặt CN
B4: Z02 | C4: 2 | D4: 13..Belt PU đen, chống tĩnh điện#2 | E4: Belt PU đen, chống tĩnh điện, dày 1.5mm, bản rộng 20mm, chu vi 670mm ( đo mép trong chu vi 677mm, căn chỉnh đã ở giữa ) | F4: Yongli | G4: 20.0 X 34.0 X 324.0 | H4: =$H$1*C4 -> 12 | I4: ='[1]Z0000002-238846 BOM trien k hai'!$I$29 -> đã chốt đặt hàng
B5: Z03 | C5: 2 | D5: KES3-12#2 | E5: chốt cài KES3-12 | F5: then cài | G5: 12.0 X 3.0 X 3.0 | H5: =$H$1*C5 -> 12 | I5: đã tồn kho sẵn
B6: Z04 | C6: 1 | D6: 13.10_MF_AL6061_1_Mirror | E6: =E30 -> AL6061, anode màu đen | F6: =F30 -> GTAM | G6: 64.0 X 75.0 X 15.0 | H6: =$H$1*C6 -> 6
B7: Z05 | C7: 2 | D7: 13.11_MF_AL6061_1#2 | E7: =E30 -> AL6061, anode màu đen | F7: =F30 -> GTAM | G7: 6.0 X 72.0 X 42.0 | H7: =$H$1*C7 -> 12
B8: Z06 | C8: 4 | D8: 13.12_MF_AL6061_1#2 | E8: =E30 -> AL6061, anode màu đen | F8: =F30 -> GTAM | G8: 12.0 X 15.0 X 34.0 | H8: =$H$1*C8 -> 24
B9: Z07 | C9: 4 | D9: 13.13_MF_AL6061_1#2 | E9: =E30 -> AL6061, anode màu đen | F9: =F30 -> GTAM | G9: 12.0 X 32.0 X 45.0 | H9: =$H$1*C9 -> 24
B10: Z08 | C10: 1 | D10: 13.14_MF_AL6061_1_Mirror | E10: =E30 -> AL6061, anode màu đen | F10: =F30 -> GTAM | G10: 90.0 X 71.0 X 10.0 | H10: =$H$1*C10 -> 6
B11: Z09 | C11: 2 | D11: 13.16_MF_AL6061_1_Mirror | E11: =E30 -> AL6061, anode màu đen | F11: =F30 -> GTAM | G11: 240.0 X 26.0 X 10.0 | H11: =$H$1*C11 -> 12
B12: Z10 | C12: 2 | D12: 13.17_MF_SUS304_1#2 | E12: ct trục, SUS304 điện hóa/ S45C mạ nikel, có lăn nhám | F12: PG | G12: 20.0 X 34.0 X 34.0 | H12: =$H$1*C12 -> 12
B13: Z11 | C13: 2 | D13: 13.18_MF_SUS304_1_Mirror | E13: ct trục, SUS304 điện hóa/ S45C mạ nikel, không lăn nhám | F13: =F12 -> PG | G13: 20.0 X 34.0 X 34.0 | H13: =$H$1*C13 -> 12
B14: Z12 | C14: 1 | D14: 13.19_MF_SUS304_1#2 | E14: ct trục, SUS304 điện hóa/ S45C mạ nikel | F14: PG | G14: 12.0 X 206.0 X 12.0 | H14: =$H$1*C14 -> 6
B15: Z13 | C15: 1 | D15: 13.1_MF_AL6061_1_Mirror | E15: =E30 -> AL6061, anode màu đen | F15: =F30 -> GTAM | G15: 330.0 X 300.0 X 10.0 | H15: =$H$1*C15 -> 6
B16: Z14 | C16: 2 | D16: 13.20_MF_SUS304_1#2 | E16: ct phay, SUS304 điện hóa hoặc S45C mạ nikel | F16: Vitech | G16: 24.0 X 20.0 X 17.0 | H16: =$H$1*C16 -> 12 | I16: đang yc gửi báo giá
B17: Z15 | C17: 1 | D17: 13.21_MF_SUS304_1_Mirror | E17: SUS304 điện hóa | F17: CG | G17: 20.0 X 29.0 X 65.0 | H17: =$H$1*C17 -> 6
B18: Z16 | C18: 1 | D18: 13.22_MF_SUS304_1_Mirror | E18: SUS304 điện hóa | F18: CG | G18: 300.0 X 43.0 X 10.0 | H18: =$H$1*C18 -> 6
B19: Z17 | C19: 1 | D19: 13.23_MF_SUS304_1_Mirror | E19: SUS304 điện hóa | F19: CG | G19: 49.0 X 79.0 X 30.0 | H19: =$H$1*C19 -> 6
B20: Z18 | C20: 1 | D20: 13.24_MF_SUS304_1#2 | E20: SUS304 điện hóa | F20: CG | G20: 13.0 X 92.0 X 17.0 | H20: =$H$1*C20 -> 6
B21: Z19 | C21: 2 | D21: 13.25_MF_SUS304_1#2 | E21: SUS304 điện hóa | F21: CG | G21: 250.0 X 23.0 X 20.0 | H21: =$H$1*C21 -> 12
B22: Z20 | C22: 1 | D22: 13.26_MF_SUS304_1_Mirror | E22: SUS304 điện hóa | F22: CG | G22: 63.0 X 28.0 X 170.0 | H22: =$H$1*C22 -> 6
B23: Z21 | C23: 2 | D23: 13.27_MF_SUS304_1_Mirror | E23: SUS304 điện hóa | F23: LINH | G23: 39.0 X 10.0 X 10.0 | H23: =$H$1*C23 -> 12 | I23: ='Z0000002-238848 BOM trien k hai'!I17 -> Ng đã đặt NCC mới cho đủ 84CV
B24: Z22 | C24: 1 | D24: 13.2_MF_AL6061_1_Mirror | E24: =E30 -> AL6061, anode màu đen | F24: =F30 -> GTAM | G24: 330.0 X 100.0 X 10.0 | H24: =$H$1*C24 -> 6
B25: Z23 | C25: 1 | D25: 13.3_MF_AL6061_1_Mirror | E25: =E30 -> AL6061, anode màu đen | F25: =F30 -> GTAM | G25: 330.0 X 10.0 X 100.0 | H25: =$H$1*C25 -> 6
B26: Z24 | C26: 1 | D26: 13.4_MF_AL6061_1#2 | E26: =E30 -> AL6061, anode màu đen | F26: =F30 -> GTAM | G26: 472.0 X 43.0 X 8.0 | H26: =$H$1*C26 -> 6
B27: Z25 | C27: 2 | D27: 13.5_MF_AL6061_1#2 | E27: =E30 -> AL6061, anode màu đen | F27: =F30 -> GTAM | G27: 33.0 X 32.0 X 10.0 | H27: =$H$1*C27 -> 12
B28: Z26 | C28: 4 | D28: 13.688AZZ_NSK_Mirror | E28: Vòng bi 688AZZ, NSK | F28: VB | G28: 5.0 X 16.0 X 16.0 | H28: =$H$1*C28 -> 24
B29: Z27 | C29: 2 | D29: 13.6_MF_AL6061_1#2 | E29: AL6061, anode màu đen | F29: =F30 -> GTAM | G29: 10.0 X 30.0 X 29.0 | H29: =$H$1*C29 -> 12
B30: Z28 | C30: 2 | D30: 13.7_MF_AL6061_1#2 | E30: AL6061, anode màu đen | F30: GTAM | G30: 10.0 X 30.0 X 10.0 | H30: =$H$1*C30 -> 12
B31: Z29 | C31: 1 | D31: 13.8_MF_AL6061_1#2 | E31: =E30 -> AL6061, anode màu đen | F31: =F30 -> GTAM | G31: 20.0 X 41.0 X 42.0 | H31: =$H$1*C31 -> 6
B32: Z30 | C32: 2 | D32: 13.9_MF_AL6061_1_Mirror | E32: =E30 -> AL6061, anode màu đen | F32: =F30 -> GTAM | G32: 225.0 X 33.0 X 10.0 | H32: =$H$1*C32 -> 12
B33: Z31 | C33: 1 | D33: 13.SPG S6I06GX-V12_Mirror | E33: động cơ SPG S6I06GX-V12/ bộ điều khiển tốc độ đi kèm | F33: SPG | G33: 88.0 X 60.0 X 62.0 | H33: =$H$1*C33 -> 6
B34: Z32 | C34: 1 | D34: 13.SPG S6KA30B_Mirror | E34: Hộp số SPG S6KA30B | F34: SPG | G34: 73.0 X 60.0 X 60.0 | H34: =$H$1*C34 -> 6
B35: Z33 | C35: 1 | D35: HTBN339S3M-150#2 | E35: HTBN339S3M-150 --> đổi sang C-HTBN225S3M-150 | F35: MI | G35: 157.0 X 25.0 X 15.0 | H35: =$H$1*C35 -> 6 | I35: đã báo a VA đặt hàng
B36: Z34 | C36: 2 | D36: HTPA25S3M150-A-N8_Mirror | E36: HTPA25S3M150-A-N8 | F36: UP | G36: 21.0 X 28.0 X 28.0 | H36: =$H$1*C36 -> 12 | I36: ='[1]Z0000002-238846 BOM trien k hai'!$I$79 -> đã đặt hàng, dự kiến 26/3 gửi hàng
B37: Z35 | C37: 1 | D37: MF_MICA_2_Mirror | E37: Mica trong | F37: =F30 -> GTAM | G37: 51.0 X 3.0 X 166.0 | H37: =$H$1*C37 -> 6
B38: Z36 | C38: 4 | D38: HI_SETGS12-89-SC65-M6-N6#2 | E38: chân đỡ thân máy SETGS12-89-SC65-M6-N6 | F38: LINH | G38: 98.0 X 12.0 X 12.0 | H38: =$H$1*C38 -> 24 | I38: =I23 -> Ng đã đặt NCC mới cho đủ 84CV
B39: Z37 | C39: 1 | D39: 13.10_MF_AL6061_1_MIR_Mirror | E39: =E6 -> AL6061, anode màu đen | F39: =F6 -> GTAM | G39: 64.0 X 75.0 X 15.0 | H39: =$H$1*C39 -> 6
B40: Z38 | C40: 2 | D40: 13.B6000ZZ#1 | E40: =E3 -> Vòng bi B6000ZZ | F40: =F3 -> VB | G40: 8.0 X 26.0 X 26.0 | H40: =$H$1*C40 -> 12 | I40: =I3 -> đã đặt CN
...
